Workbook

Sheet Como usar
B1: COMO USAR – Escola Modelo (dados fictícios)
B2: Células em bege = você preenche. Células brancas = calculam sozinhas (não apague). Campos com ▼ = escolha da lista.
B4: 1. ANTES DE COMEÇAR (uma vez só)
B5: 1 | C5: Aba Config: preencha o dia de vencimento do boleto, multa, juros, tarifa por boleto e o saldo inicial do caixa.
B6: 2 | C6: Aba Config: preencha o valor da mensalidade de cada turma e o valor do Judô e do Balé.
B7: 3 | C7: Aba Alunos: confira a turma de cada aluno, marque Judô/Balé, desconto (se houver) e preencha o CPF do responsável.
B8: 4 | C8: Aba Despesas Fixas: cadastre as contas que se repetem todo mês (aluguel, salários, internet, contador...).
B9: 5 | C9: Não apague nada nas colunas brancas – são elas que fazem a planilha calcular sozinha.
B11: 2. NO DIA A DIA
B12: 1 | C12: Boleto pago: na aba Boletos, coloque a data do pagamento (e o nº do boleto da plataforma de cobrança, se quiser). Valor pago só se for diferente.
B13: 2 | C13: Conta fixa paga: na aba Contas Fixas, coloque a data do pagamento.
B14: 3 | C14: Outra despesa (conserto, material, evento...): lance na aba Despesas com vencimento, categoria, tipo e valor. Quando pagar, coloque a data.
B15: 4 | C15: Dinheiro que não veio de boleto (matrícula, uniforme, festa...): lance na aba Outras Receitas.
B16: 5 | C16: Boleto cancelado na plataforma de cobrança: marque Sim em Cancelado? na aba Boletos.
B18: 3. ACOMPANHAMENTO
B19: 1 | C19: Aba Resumo: receitas, despesas, saldo de cada mês e indicadores. O aviso no topo diz se falta algo ou se está tudo em dia.
B20: 2 | C20: Aba Pendências: lista sozinha os boletos vencidos (com multa e juros) e os cadastros sem CPF.
B21: 3 | C21: Status com cores: verde = pago, vermelho = vencido/atrasado, amarelo = a vencer.
B23: 4. ALUNOS
B24: 1 | C24: Aluno novo: escreva o nome na primeira linha vazia da aba Alunos e escolha a turma – os 12 boletos são criados sozinhos.
B25: 2 | C25: A aba Alunos A-Z mostra todos em ordem alfabética, atualizando sozinha. Não classifique (A→Z) a aba Alunos: isso desalinha os pagamentos da aba Boletos.
B26: 3 | C26: Mudou de turma: troque a turma na coluna ao lado do nome – mensalidade e boletos se atualizam.
B27: 4 | C27: Aluno saiu: mude a Situação para Inativo – ele para de gerar boletos.
B28: 5 | C28: Entrou ou vai sair no meio do ano: escolha o Mês de entrada / Mês de saída – os boletos só são gerados nos meses certos.
B30: 5. VIRADA DE ANO
B31: 1 | C31: Faça uma cópia do arquivo e renomeie com o novo ano (ex.: 2028). Guarde o arquivo antigo como histórico.
B32: 2 | C32: Config: troque o ano, ajuste as mensalidades e coloque como saldo inicial o saldo de dezembro do ano anterior.
B33: 3 | C33: Alunos: suba as turmas, marque Inativo quem saiu e cadastre os novos.
B34: 4 | C34: Apague só as colunas em bege das abas Boletos e Contas Fixas, e os lançamentos de Despesas e Outras Receitas.
B36: DICAS
B37: 1 | C37: Atalho para a data de hoje no Excel: Ctrl + ; | No Google Planilhas, clique 2x na célula de data para abrir o calendário.
B38: 2 | C38: Use os filtros no cabeçalho das abas Boletos e Despesas para ver só um aluno, só um mês ou só os vencidos.
B39: 3 | C39: As células de fórmula estão protegidas contra apagamento acidental (sem senha). Para liberar: Revisão → Desproteger Planilha.

Sheet Resumo
A1: ="Resumo financeiro – "&Config!B3&" – "&Config!B4
A2: =IF(Config!B5="","⚠ Preencha o dia de vencimento na aba Config",IF(COUNTBLANK(Config!B14:B17)>0,"⚠ Preencha o valor das mensalidades na aba Config",IF(COUNTIF(Boletos!J3:J3602,"Vencido")>0,"⚠ Existem "&COUNTIF(Boletos!J3:J3602,"Vencido")&" boletos vencidos – veja a aba Pendências",IF(COUNTIF('Contas Fixas'!I3:I362,"Atrasada")>0,"⚠ Existem "&COUNTIF('Contas Fixas'!I3:I362,"Atrasada")&" contas fixas atrasadas – veja a aba Contas Fixas","✓ Tudo em dia"))))
A3: Mês | B3: Boletos previstos | C3: Boletos recebidos | D3: Outras receitas | E3: Total receitas | F3: Despesas pagas | G3: Tarifas de boleto | H3: Resultado | I3: Saldo acumulado
A4: Jan | B4: =SUMIFS(Boletos!$E$3:$E$3602,Boletos!$C$3:$C$3602,A4,Boletos!$J$3:$J$3602,"<>Cancelado") | C4: =SUMIFS(Boletos!$N$3:$N$3602,Boletos!$M$3:$M$3602,1) | D4: =SUMIFS('Outras Receitas'!$D$2:$D$500,'Outras Receitas'!$E$2:$E$500,1) | E4: =C4+D4 | F4: =SUMIFS(Despesas!$F$2:$F$1000,Despesas!$I$2:$I$1000,1)+SUMIFS('Contas Fixas'!$K$3:$K$362,'Contas Fixas'!$J$3:$J$362,1) | G4: =COUNTIFS(Boletos!$M$3:$M$3602,1)*Config!$B$8 | H4: =E4-F4-G4 | I4: =Config!$B$9+H4
A5: Fev | B5: =SUMIFS(Boletos!$E$3:$E$3602,Boletos!$C$3:$C$3602,A5,Boletos!$J$3:$J$3602,"<>Cancelado") | C5: =SUMIFS(Boletos!$N$3:$N$3602,Boletos!$M$3:$M$3602,2) | D5: =SUMIFS('Outras Receitas'!$D$2:$D$500,'Outras Receitas'!$E$2:$E$500,2) | E5: =C5+D5 | F5: =SUMIFS(Despesas!$F$2:$F$1000,Despesas!$I$2:$I$1000,2)+SUMIFS('Contas Fixas'!$K$3:$K$362,'Contas Fixas'!$J$3:$J$362,2) | G5: =COUNTIFS(Boletos!$M$3:$M$3602,2)*Config!$B$8 | H5: =E5-F5-G5 | I5: =I4+H5
A6: Mar | B6: =SUMIFS(Boletos!$E$3:$E$3602,Boletos!$C$3:$C$3602,A6,Boletos!$J$3:$J$3602,"<>Cancelado") | C6: =SUMIFS(Boletos!$N$3:$N$3602,Boletos!$M$3:$M$3602,3) | D6: =SUMIFS('Outras Receitas'!$D$2:$D$500,'Outras Receitas'!$E$2:$E$500,3) | E6: =C6+D6 | F6: =SUMIFS(Despesas!$F$2:$F$1000,Despesas!$I$2:$I$1000,3)+SUMIFS('Contas Fixas'!$K$3:$K$362,'Contas Fixas'!$J$3:$J$362,3) | G6: =COUNTIFS(Boletos!$M$3:$M$3602,3)*Config!$B$8 | H6: =E6-F6-G6 | I6: =I5+H6
A7: Abr | B7: =SUMIFS(Boletos!$E$3:$E$3602,Boletos!$C$3:$C$3602,A7,Boletos!$J$3:$J$3602,"<>Cancelado") | C7: =SUMIFS(Boletos!$N$3:$N$3602,Boletos!$M$3:$M$3602,4) | D7: =SUMIFS('Outras Receitas'!$D$2:$D$500,'Outras Receitas'!$E$2:$E$500,4) | E7: =C7+D7 | F7: =SUMIFS(Despesas!$F$2:$F$1000,Despesas!$I$2:$I$1000,4)+SUMIFS('Contas Fixas'!$K$3:$K$362,'Contas Fixas'!$J$3:$J$362,4) | G7: =COUNTIFS(Boletos!$M$3:$M$3602,4)*Config!$B$8 | H7: =E7-F7-G7 | I7: =I6+H7
A8: Mai | B8: =SUMIFS(Boletos!$E$3:$E$3602,Boletos!$C$3:$C$3602,A8,Boletos!$J$3:$J$3602,"<>Cancelado") | C8: =SUMIFS(Boletos!$N$3:$N$3602,Boletos!$M$3:$M$3602,5) | D8: =SUMIFS('Outras Receitas'!$D$2:$D$500,'Outras Receitas'!$E$2:$E$500,5) | E8: =C8+D8 | F8: =SUMIFS(Despesas!$F$2:$F$1000,Despesas!$I$2:$I$1000,5)+SUMIFS('Contas Fixas'!$K$3:$K$362,'Contas Fixas'!$J$3:$J$362,5) | G8: =COUNTIFS(Boletos!$M$3:$M$3602,5)*Config!$B$8 | H8: =E8-F8-G8 | I8: =I7+H8
A9: Jun | B9: =SUMIFS(Boletos!$E$3:$E$3602,Boletos!$C$3:$C$3602,A9,Boletos!$J$3:$J$3602,"<>Cancelado") | C9: =SUMIFS(Boletos!$N$3:$N$3602,Boletos!$M$3:$M$3602,6) | D9: =SUMIFS('Outras Receitas'!$D$2:$D$500,'Outras Receitas'!$E$2:$E$500,6) | E9: =C9+D9 | F9: =SUMIFS(Despesas!$F$2:$F$1000,Despesas!$I$2:$I$1000,6)+SUMIFS('Contas Fixas'!$K$3:$K$362,'Contas Fixas'!$J$3:$J$362,6) | G9: =COUNTIFS(Boletos!$M$3:$M$3602,6)*Config!$B$8 | H9: =E9-F9-G9 | I9: =I8+H9
A10: Jul | B10: =SUMIFS(Boletos!$E$3:$E$3602,Boletos!$C$3:$C$3602,A10,Boletos!$J$3:$J$3602,"<>Cancelado") | C10: =SUMIFS(Boletos!$N$3:$N$3602,Boletos!$M$3:$M$3602,7) | D10: =SUMIFS('Outras Receitas'!$D$2:$D$500,'Outras Receitas'!$E$2:$E$500,7) | E10: =C10+D10 | F10: =SUMIFS(Despesas!$F$2:$F$1000,Despesas!$I$2:$I$1000,7)+SUMIFS('Contas Fixas'!$K$3:$K$362,'Contas Fixas'!$J$3:$J$362,7) | G10: =COUNTIFS(Boletos!$M$3:$M$3602,7)*Config!$B$8 | H10: =E10-F10-G10 | I10: =I9+H10
A11: Ago | B11: =SUMIFS(Boletos!$E$3:$E$3602,Boletos!$C$3:$C$3602,A11,Boletos!$J$3:$J$3602,"<>Cancelado") | C11: =SUMIFS(Boletos!$N$3:$N$3602,Boletos!$M$3:$M$3602,8) | D11: =SUMIFS('Outras Receitas'!$D$2:$D$500,'Outras Receitas'!$E$2:$E$500,8) | E11: =C11+D11 | F11: =SUMIFS(Despesas!$F$2:$F$1000,Despesas!$I$2:$I$1000,8)+SUMIFS('Contas Fixas'!$K$3:$K$362,'Contas Fixas'!$J$3:$J$362,8) | G11: =COUNTIFS(Boletos!$M$3:$M$3602,8)*Config!$B$8 | H11: =E11-F11-G11 | I11: =I10+H11
A12: Set | B12: =SUMIFS(Boletos!$E$3:$E$3602,Boletos!$C$3:$C$3602,A12,Boletos!$J$3:$J$3602,"<>Cancelado") | C12: =SUMIFS(Boletos!$N$3:$N$3602,Boletos!$M$3:$M$3602,9) | D12: =SUMIFS('Outras Receitas'!$D$2:$D$500,'Outras Receitas'!$E$2:$E$500,9) | E12: =C12+D12 | F12: =SUMIFS(Despesas!$F$2:$F$1000,Despesas!$I$2:$I$1000,9)+SUMIFS('Contas Fixas'!$K$3:$K$362,'Contas Fixas'!$J$3:$J$362,9) | G12: =COUNTIFS(Boletos!$M$3:$M$3602,9)*Config!$B$8 | H12: =E12-F12-G12 | I12: =I11+H12
A13: Out | B13: =SUMIFS(Boletos!$E$3:$E$3602,Boletos!$C$3:$C$3602,A13,Boletos!$J$3:$J$3602,"<>Cancelado") | C13: =SUMIFS(Boletos!$N$3:$N$3602,Boletos!$M$3:$M$3602,10) | D13: =SUMIFS('Outras Receitas'!$D$2:$D$500,'Outras Receitas'!$E$2:$E$500,10) | E13: =C13+D13 | F13: =SUMIFS(Despesas!$F$2:$F$1000,Despesas!$I$2:$I$1000,10)+SUMIFS('Contas Fixas'!$K$3:$K$362,'Contas Fixas'!$J$3:$J$362,10) | G13: =COUNTIFS(Boletos!$M$3:$M$3602,10)*Config!$B$8 | H13: =E13-F13-G13 | I13: =I12+H13
A14: Nov | B14: =SUMIFS(Boletos!$E$3:$E$3602,Boletos!$C$3:$C$3602,A14,Boletos!$J$3:$J$3602,"<>Cancelado") | C14: =SUMIFS(Boletos!$N$3:$N$3602,Boletos!$M$3:$M$3602,11) | D14: =SUMIFS('Outras Receitas'!$D$2:$D$500,'Outras Receitas'!$E$2:$E$500,11) | E14: =C14+D14 | F14: =SUMIFS(Despesas!$F$2:$F$1000,Despesas!$I$2:$I$1000,11)+SUMIFS('Contas Fixas'!$K$3:$K$362,'Contas Fixas'!$J$3:$J$362,11) | G14: =COUNTIFS(Boletos!$M$3:$M$3602,11)*Config!$B$8 | H14: =E14-F14-G14 | I14: =I13+H14
A15: Dez | B15: =SUMIFS(Boletos!$E$3:$E$3602,Boletos!$C$3:$C$3602,A15,Boletos!$J$3:$J$3602,"<>Cancelado") | C15: =SUMIFS(Boletos!$N$3:$N$3602,Boletos!$M$3:$M$3602,12) | D15: =SUMIFS('Outras Receitas'!$D$2:$D$500,'Outras Receitas'!$E$2:$E$500,12) | E15: =C15+D15 | F15: =SUMIFS(Despesas!$F$2:$F$1000,Despesas!$I$2:$I$1000,12)+SUMIFS('Contas Fixas'!$K$3:$K$362,'Contas Fixas'!$J$3:$J$362,12) | G15: =COUNTIFS(Boletos!$M$3:$M$3602,12)*Config!$B$8 | H15: =E15-F15-G15 | I15: =I14+H15
A16: TOTAL | B16: =SUM(B4:B15) | C16: =SUM(C4:C15) | D16: =SUM(D4:D15) | E16: =SUM(E4:E15) | F16: =SUM(F4:F15) | G16: =SUM(G4:G15) | H16: =SUM(H4:H15)
A18: ="INDICADORES "&Config!B4
A19: Alunos ativos | B19: =COUNTIF(Alunos!L:L,"Ativo")+COUNTIF(Alunos!L:L,"Bolsista")
A20: Alunos no Maternal 2 | B20: =COUNTIFS(Alunos!B:B,"Maternal 2",Alunos!L:L,"<>Inativo")
A21: Alunos no Maternal 3 | B21: =COUNTIFS(Alunos!B:B,"Maternal 3",Alunos!L:L,"<>Inativo")
A22: Alunos no 1º Período | B22: =COUNTIFS(Alunos!B:B,"1º Período",Alunos!L:L,"<>Inativo")
A23: Alunos no 2º Período | B23: =COUNTIFS(Alunos!B:B,"2º Período",Alunos!L:L,"<>Inativo")
A24: Alunos no Judô | B24: =COUNTIF(Alunos!G:G,"Sim")
A25: Alunos no Balé | B25: =COUNTIF(Alunos!H:H,"Sim")
A26: Receita prevista por mês | B26: =SUM(Alunos!K2:K301)
A27: Boletos pagos | B27: =COUNTIF(Boletos!J3:J3602,"Pago")
A28: Boletos vencidos | B28: =COUNTIF(Boletos!J3:J3602,"Vencido")
A29: Valor vencido (atualizado) | B29: =SUMIFS(Boletos!L3:L3602,Boletos!J3:J3602,"Vencido")
A30: Inadimplência (% do vencido) | B30: =IFERROR(SUMIFS(Boletos!E3:E3602,Boletos!J3:J3602,"Vencido")/(SUMIFS(Boletos!E3:E3602,Boletos!J3:J3602,"Vencido")+SUMIFS(Boletos!E3:E3602,Boletos!J3:J3602,"Pago")),0)
A31: Despesas atrasadas | B31: =SUMIFS(Despesas!F:F,Despesas!H:H,"Atrasada")+SUMIFS('Contas Fixas'!F3:F362,'Contas Fixas'!I3:I362,"Atrasada")
A32: Despesas fixas pagas no ano | B32: =SUMIFS(Despesas!F:F,Despesas!D:D,"Fixa",Despesas!H:H,"Pago")+SUM('Contas Fixas'!K3:K362)
A33: Despesas variáveis pagas no ano | B33: =SUMIFS(Despesas!F:F,Despesas!D:D,"Variável",Despesas!H:H,"Pago")
A34: Margem do ano | B34: =IFERROR(H16/E16,0)

Sheet Pendências
A1: PENDÊNCIAS – atualiza sozinha
A3: Boletos vencidos | H3: Total vencido | J3: Cadastros sem CPF do responsável
A4: Aluno | B4: Responsável | C4: Mês ref. | D4: Vencimento | E4: Dias de atraso | F4: Valor atualizado | H4: =SUMIFS(Boletos!L3:L3602,Boletos!J3:J3602,"Vencido") | J4: Aluno | K4: Responsável
A5: {=IFERROR(INDEX(Boletos!$A:$A,SMALL(Boletos!$O$3:$O$3602,1)),"")} | B5: {=IFERROR(INDEX(Boletos!$B:$B,SMALL(Boletos!$O$3:$O$3602,1)),"")} | C5: {=IFERROR(INDEX(Boletos!$C:$C,SMALL(Boletos!$O$3:$O$3602,1)),"")} | D5: {=IFERROR(INDEX(Boletos!$D:$D,SMALL(Boletos!$O$3:$O$3602,1)),"")} | E5: {=IFERROR(INDEX(Boletos!$K:$K,SMALL(Boletos!$O$3:$O$3602,1)),"")} | F5: {=IFERROR(INDEX(Boletos!$L:$L,SMALL(Boletos!$O$3:$O$3602,1)),"")} | J5: {=IFERROR(INDEX(Alunos!$A:$A,SMALL(Alunos!$O$2:$O$301,1)),"")} | K5: {=IFERROR(INDEX(Alunos!$C:$C,SMALL(Alunos!$O$2:$O$301,1)),"")}
A6: {=IFERROR(INDEX(Boletos!$A:$A,SMALL(Boletos!$O$3:$O$3602,2)),"")} | B6: {=IFERROR(INDEX(Boletos!$B:$B,SMALL(Boletos!$O$3:$O$3602,2)),"")} | C6: {=IFERROR(INDEX(Boletos!$C:$C,SMALL(Boletos!$O$3:$O$3602,2)),"")} | D6: {=IFERROR(INDEX(Boletos!$D:$D,SMALL(Boletos!$O$3:$O$3602,2)),"")} | E6: {=IFERROR(INDEX(Boletos!$K:$K,SMALL(Boletos!$O$3:$O$3602,2)),"")} | F6: {=IFERROR(INDEX(Boletos!$L:$L,SMALL(Boletos!$O$3:$O$3602,2)),"")} | H6: Boletos vencidos | J6: {=IFERROR(INDEX(Alunos!$A:$A,SMALL(Alunos!$O$2:$O$301,2)),"")} | K6: {=IFERROR(INDEX(Alunos!$C:$C,SMALL(Alunos!$O$2:$O$301,2)),"")}
A7: {=IFERROR(INDEX(Boletos!$A:$A,SMALL(Boletos!$O$3:$O$3602,3)),"")} | B7: {=IFERROR(INDEX(Boletos!$B:$B,SMALL(Boletos!$O$3:$O$3602,3)),"")} | C7: {=IFERROR(INDEX(Boletos!$C:$C,SMALL(Boletos!$O$3:$O$3602,3)),"")} | D7: {=IFERROR(INDEX(Boletos!$D:$D,SMALL(Boletos!$O$3:$O$3602,3)),"")} | E7: {=IFERROR(INDEX(Boletos!$K:$K,SMALL(Boletos!$O$3:$O$3602,3)),"")} | F7: {=IFERROR(INDEX(Boletos!$L:$L,SMALL(Boletos!$O$3:$O$3602,3)),"")} | H7: =COUNTIF(Boletos!J3:J3602,"Vencido") | J7: {=IFERROR(INDEX(Alunos!$A:$A,SMALL(Alunos!$O$2:$O$301,3)),"")} | K7: {=IFERROR(INDEX(Alunos!$C:$C,SMALL(Alunos!$O$2:$O$301,3)),"")}
A8: {=IFERROR(INDEX(Boletos!$A:$A,SMALL(Boletos!$O$3:$O$3602,4)),"")} | B8: {=IFERROR(INDEX(Boletos!$B:$B,SMALL(Boletos!$O$3:$O$3602,4)),"")} | C8: {=IFERROR(INDEX(Boletos!$C:$C,SMALL(Boletos!$O$3:$O$3602,4)),"")} | D8: {=IFERROR(INDEX(Boletos!$D:$D,SMALL(Boletos!$O$3:$O$3602,4)),"")} | E8: {=IFERROR(INDEX(Boletos!$K:$K,SMALL(Boletos!$O$3:$O$3602,4)),"")} | F8: {=IFERROR(INDEX(Boletos!$L:$L,SMALL(Boletos!$O$3:$O$3602,4)),"")} | J8: {=IFERROR(INDEX(Alunos!$A:$A,SMALL(Alunos!$O$2:$O$301,4)),"")} | K8: {=IFERROR(INDEX(Alunos!$C:$C,SMALL(Alunos!$O$2:$O$301,4)),"")}
A9: {=IFERROR(INDEX(Boletos!$A:$A,SMALL(Boletos!$O$3:$O$3602,5)),"")} | B9: {=IFERROR(INDEX(Boletos!$B:$B,SMALL(Boletos!$O$3:$O$3602,5)),"")} | C9: {=IFERROR(INDEX(Boletos!$C:$C,SMALL(Boletos!$O$3:$O$3602,5)),"")} | D9: {=IFERROR(INDEX(Boletos!$D:$D,SMALL(Boletos!$O$3:$O$3602,5)),"")} | E9: {=IFERROR(INDEX(Boletos!$K:$K,SMALL(Boletos!$O$3:$O$3602,5)),"")} | F9: {=IFERROR(INDEX(Boletos!$L:$L,SMALL(Boletos!$O$3:$O$3602,5)),"")} | H9: Contas fixas atrasadas | J9: {=IFERROR(INDEX(Alunos!$A:$A,SMALL(Alunos!$O$2:$O$301,5)),"")} | K9: {=IFERROR(INDEX(Alunos!$C:$C,SMALL(Alunos!$O$2:$O$301,5)),"")}
A10: {=IFERROR(INDEX(Boletos!$A:$A,SMALL(Boletos!$O$3:$O$3602,6)),"")} | B10: {=IFERROR(INDEX(Boletos!$B:$B,SMALL(Boletos!$O$3:$O$3602,6)),"")} | C10: {=IFERROR(INDEX(Boletos!$C:$C,SMALL(Boletos!$O$3:$O$3602,6)),"")} | D10: {=IFERROR(INDEX(Boletos!$D:$D,SMALL(Boletos!$O$3:$O$3602,6)),"")} | E10: {=IFERROR(INDEX(Boletos!$K:$K,SMALL(Boletos!$O$3:$O$3602,6)),"")} | F10: {=IFERROR(INDEX(Boletos!$L:$L,SMALL(Boletos!$O$3:$O$3602,6)),"")} | H10: =COUNTIF('Contas Fixas'!I3:I362,"Atrasada") | J10: {=IFERROR(INDEX(Alunos!$A:$A,SMALL(Alunos!$O$2:$O$301,6)),"")} | K10: {=IFERROR(INDEX(Alunos!$C:$C,SMALL(Alunos!$O$2:$O$301,6)),"")}
A11: {=IFERROR(INDEX(Boletos!$A:$A,SMALL(Boletos!$O$3:$O$3602,7)),"")} | B11: {=IFERROR(INDEX(Boletos!$B:$B,SMALL(Boletos!$O$3:$O$3602,7)),"")} | C11: {=IFERROR(INDEX(Boletos!$C:$C,SMALL(Boletos!$O$3:$O$3602,7)),"")} | D11: {=IFERROR(INDEX(Boletos!$D:$D,SMALL(Boletos!$O$3:$O$3602,7)),"")} | E11: {=IFERROR(INDEX(Boletos!$K:$K,SMALL(Boletos!$O$3:$O$3602,7)),"")} | F11: {=IFERROR(INDEX(Boletos!$L:$L,SMALL(Boletos!$O$3:$O$3602,7)),"")} | J11: {=IFERROR(INDEX(Alunos!$A:$A,SMALL(Alunos!$O$2:$O$301,7)),"")} | K11: {=IFERROR(INDEX(Alunos!$C:$C,SMALL(Alunos!$O$2:$O$301,7)),"")}
A12: {=IFERROR(INDEX(Boletos!$A:$A,SMALL(Boletos!$O$3:$O$3602,8)),"")} | B12: {=IFERROR(INDEX(Boletos!$B:$B,SMALL(Boletos!$O$3:$O$3602,8)),"")} | C12: {=IFERROR(INDEX(Boletos!$C:$C,SMALL(Boletos!$O$3:$O$3602,8)),"")} | D12: {=IFERROR(INDEX(Boletos!$D:$D,SMALL(Boletos!$O$3:$O$3602,8)),"")} | E12: {=IFERROR(INDEX(Boletos!$K:$K,SMALL(Boletos!$O$3:$O$3602,8)),"")} | F12: {=IFERROR(INDEX(Boletos!$L:$L,SMALL(Boletos!$O$3:$O$3602,8)),"")} | J12: {=IFERROR(INDEX(Alunos!$A:$A,SMALL(Alunos!$O$2:$O$301,8)),"")} | K12: {=IFERROR(INDEX(Alunos!$C:$C,SMALL(Alunos!$O$2:$O$301,8)),"")}
A13: {=IFERROR(INDEX(Boletos!$A:$A,SMALL(Boletos!$O$3:$O$3602,9)),"")} | B13: {=IFERROR(INDEX(Boletos!$B:$B,SMALL(Boletos!$O$3:$O$3602,9)),"")} | C13: {=IFERROR(INDEX(Boletos!$C:$C,SMALL(Boletos!$O$3:$O$3602,9)),"")} | D13: {=IFERROR(INDEX(Boletos!$D:$D,SMALL(Boletos!$O$3:$O$3602,9)),"")} | E13: {=IFERROR(INDEX(Boletos!$K:$K,SMALL(Boletos!$O$3:$O$3602,9)),"")} | F13: {=IFERROR(INDEX(Boletos!$L:$L,SMALL(Boletos!$O$3:$O$3602,9)),"")} | J13: {=IFERROR(INDEX(Alunos!$A:$A,SMALL(Alunos!$O$2:$O$301,9)),"")} | K13: {=IFERROR(INDEX(Alunos!$C:$C,SMALL(Alunos!$O$2:$O$301,9)),"")}
A14: {=IFERROR(INDEX(Boletos!$A:$A,SMALL(Boletos!$O$3:$O$3602,10)),"")} | B14: {=IFERROR(INDEX(Boletos!$B:$B,SMALL(Boletos!$O$3:$O$3602,10)),"")} | C14: {=IFERROR(INDEX(Boletos!$C:$C,SMALL(Boletos!$O$3:$O$3602,10)),"")} | D14: {=IFERROR(INDEX(Boletos!$D:$D,SMALL(Boletos!$O$3:$O$3602,10)),"")} | E14: {=IFERROR(INDEX(Boletos!$K:$K,SMALL(Boletos!$O$3:$O$3602,10)),"")} | F14: {=IFERROR(INDEX(Boletos!$L:$L,SMALL(Boletos!$O$3:$O$3602,10)),"")} | J14: {=IFERROR(INDEX(Alunos!$A:$A,SMALL(Alunos!$O$2:$O$301,10)),"")} | K14: {=IFERROR(INDEX(Alunos!$C:$C,SMALL(Alunos!$O$2:$O$301,10)),"")}
A15: {=IFERROR(INDEX(Boletos!$A:$A,SMALL(Boletos!$O$3:$O$3602,11)),"")} | B15: {=IFERROR(INDEX(Boletos!$B:$B,SMALL(Boletos!$O$3:$O$3602,11)),"")} | C15: {=IFERROR(INDEX(Boletos!$C:$C,SMALL(Boletos!$O$3:$O$3602,11)),"")} | D15: {=IFERROR(INDEX(Boletos!$D:$D,SMALL(Boletos!$O$3:$O$3602,11)),"")} | E15: {=IFERROR(INDEX(Boletos!$K:$K,SMALL(Boletos!$O$3:$O$3602,11)),"")} | F15: {=IFERROR(INDEX(Boletos!$L:$L,SMALL(Boletos!$O$3:$O$3602,11)),"")} | J15: {=IFERROR(INDEX(Alunos!$A:$A,SMALL(Alunos!$O$2:$O$301,11)),"")} | K15: {=IFERROR(INDEX(Alunos!$C:$C,SMALL(Alunos!$O$2:$O$301,11)),"")}
A16: {=IFERROR(INDEX(Boletos!$A:$A,SMALL(Boletos!$O$3:$O$3602,12)),"")} | B16: {=IFERROR(INDEX(Boletos!$B:$B,SMALL(Boletos!$O$3:$O$3602,12)),"")} | C16: {=IFERROR(INDEX(Boletos!$C:$C,SMALL(Boletos!$O$3:$O$3602,12)),"")} | D16: {=IFERROR(INDEX(Boletos!$D:$D,SMALL(Boletos!$O$3:$O$3602,12)),"")} | E16: {=IFERROR(INDEX(Boletos!$K:$K,SMALL(Boletos!$O$3:$O$3602,12)),"")} | F16: {=IFERROR(INDEX(Boletos!$L:$L,SMALL(Boletos!$O$3:$O$3602,12)),"")} | J16: {=IFERROR(INDEX(Alunos!$A:$A,SMALL(Alunos!$O$2:$O$301,12)),"")} | K16: {=IFERROR(INDEX(Alunos!$C:$C,SMALL(Alunos!$O$2:$O$301,12)),"")}
A17: {=IFERROR(INDEX(Boletos!$A:$A,SMALL(Boletos!$O$3:$O$3602,13)),"")} | B17: {=IFERROR(INDEX(Boletos!$B:$B,SMALL(Boletos!$O$3:$O$3602,13)),"")} | C17: {=IFERROR(INDEX(Boletos!$C:$C,SMALL(Boletos!$O$3:$O$3602,13)),"")} | D17: {=IFERROR(INDEX(Boletos!$D:$D,SMALL(Boletos!$O$3:$O$3602,13)),"")} | E17: {=IFERROR(INDEX(Boletos!$K:$K,SMALL(Boletos!$O$3:$O$3602,13)),"")} | F17: {=IFERROR(INDEX(Boletos!$L:$L,SMALL(Boletos!$O$3:$O$3602,13)),"")} | J17: {=IFERROR(INDEX(Alunos!$A:$A,SMALL(Alunos!$O$2:$O$301,13)),"")} | K17: {=IFERROR(INDEX(Alunos!$C:$C,SMALL(Alunos!$O$2:$O$301,13)),"")}
A18: {=IFERROR(INDEX(Boletos!$A:$A,SMALL(Boletos!$O$3:$O$3602,14)),"")} | B18: {=IFERROR(INDEX(Boletos!$B:$B,SMALL(Boletos!$O$3:$O$3602,14)),"")} | C18: {=IFERROR(INDEX(Boletos!$C:$C,SMALL(Boletos!$O$3:$O$3602,14)),"")} | D18: {=IFERROR(INDEX(Boletos!$D:$D,SMALL(Boletos!$O$3:$O$3602,14)),"")} | E18: {=IFERROR(INDEX(Boletos!$K:$K,SMALL(Boletos!$O$3:$O$3602,14)),"")} | F18: {=IFERROR(INDEX(Boletos!$L:$L,SMALL(Boletos!$O$3:$O$3602,14)),"")} | J18: {=IFERROR(INDEX(Alunos!$A:$A,SMALL(Alunos!$O$2:$O$301,14)),"")} | K18: {=IFERROR(INDEX(Alunos!$C:$C,SMALL(Alunos!$O$2:$O$301,14)),"")}
A19: {=IFERROR(INDEX(Boletos!$A:$A,SMALL(Boletos!$O$3:$O$3602,15)),"")} | B19: {=IFERROR(INDEX(Boletos!$B:$B,SMALL(Boletos!$O$3:$O$3602,15)),"")} | C19: {=IFERROR(INDEX(Boletos!$C:$C,SMALL(Boletos!$O$3:$O$3602,15)),"")} | D19: {=IFERROR(INDEX(Boletos!$D:$D,SMALL(Boletos!$O$3:$O$3602,15)),"")} | E19: {=IFERROR(INDEX(Boletos!$K:$K,SMALL(Boletos!$O$3:$O$3602,15)),"")} | F19: {=IFERROR(INDEX(Boletos!$L:$L,SMALL(Boletos!$O$3:$O$3602,15)),"")} | J19: {=IFERROR(INDEX(Alunos!$A:$A,SMALL(Alunos!$O$2:$O$301,15)),"")} | K19: {=IFERROR(INDEX(Alunos!$C:$C,SMALL(Alunos!$O$2:$O$301,15)),"")}
A20: {=IFERROR(INDEX(Boletos!$A:$A,SMALL(Boletos!$O$3:$O$3602,16)),"")} | B20: {=IFERROR(INDEX(Boletos!$B:$B,SMALL(Boletos!$O$3:$O$3602,16)),"")} | C20: {=IFERROR(INDEX(Boletos!$C:$C,SMALL(Boletos!$O$3:$O$3602,16)),"")} | D20: {=IFERROR(INDEX(Boletos!$D:$D,SMALL(Boletos!$O$3:$O$3602,16)),"")} | E20: {=IFERROR(INDEX(Boletos!$K:$K,SMALL(Boletos!$O$3:$O$3602,16)),"")} | F20: {=IFERROR(INDEX(Boletos!$L:$L,SMALL(Boletos!$O$3:$O$3602,16)),"")} | J20: {=IFERROR(INDEX(Alunos!$A:$A,SMALL(Alunos!$O$2:$O$301,16)),"")} | K20: {=IFERROR(INDEX(Alunos!$C:$C,SMALL(Alunos!$O$2:$O$301,16)),"")}
A21: {=IFERROR(INDEX(Boletos!$A:$A,SMALL(Boletos!$O$3:$O$3602,17)),"")} | B21: {=IFERROR(INDEX(Boletos!$B:$B,SMALL(Boletos!$O$3:$O$3602,17)),"")} | C21: {=IFERROR(INDEX(Boletos!$C:$C,SMALL(Boletos!$O$3:$O$3602,17)),"")} | D21: {=IFERROR(INDEX(Boletos!$D:$D,SMALL(Boletos!$O$3:$O$3602,17)),"")} | E21: {=IFERROR(INDEX(Boletos!$K:$K,SMALL(Boletos!$O$3:$O$3602,17)),"")} | F21: {=IFERROR(INDEX(Boletos!$L:$L,SMALL(Boletos!$O$3:$O$3602,17)),"")} | J21: {=IFERROR(INDEX(Alunos!$A:$A,SMALL(Alunos!$O$2:$O$301,17)),"")} | K21: {=IFERROR(INDEX(Alunos!$C:$C,SMALL(Alunos!$O$2:$O$301,17)),"")}
A22: {=IFERROR(INDEX(Boletos!$A:$A,SMALL(Boletos!$O$3:$O$3602,18)),"")} | B22: {=IFERROR(INDEX(Boletos!$B:$B,SMALL(Boletos!$O$3:$O$3602,18)),"")} | C22: {=IFERROR(INDEX(Boletos!$C:$C,SMALL(Boletos!$O$3:$O$3602,18)),"")} | D22: {=IFERROR(INDEX(Boletos!$D:$D,SMALL(Boletos!$O$3:$O$3602,18)),"")} | E22: {=IFERROR(INDEX(Boletos!$K:$K,SMALL(Boletos!$O$3:$O$3602,18)),"")} | F22: {=IFERROR(INDEX(Boletos!$L:$L,SMALL(Boletos!$O$3:$O$3602,18)),"")} | J22: {=IFERROR(INDEX(Alunos!$A:$A,SMALL(Alunos!$O$2:$O$301,18)),"")} | K22: {=IFERROR(INDEX(Alunos!$C:$C,SMALL(Alunos!$O$2:$O$301,18)),"")}
A23: {=IFERROR(INDEX(Boletos!$A:$A,SMALL(Boletos!$O$3:$O$3602,19)),"")} | B23: {=IFERROR(INDEX(Boletos!$B:$B,SMALL(Boletos!$O$3:$O$3602,19)),"")} | C23: {=IFERROR(INDEX(Boletos!$C:$C,SMALL(Boletos!$O$3:$O$3602,19)),"")} | D23: {=IFERROR(INDEX(Boletos!$D:$D,SMALL(Boletos!$O$3:$O$3602,19)),"")} | E23: {=IFERROR(INDEX(Boletos!$K:$K,SMALL(Boletos!$O$3:$O$3602,19)),"")} | F23: {=IFERROR(INDEX(Boletos!$L:$L,SMALL(Boletos!$O$3:$O$3602,19)),"")} | J23: {=IFERROR(INDEX(Alunos!$A:$A,SMALL(Alunos!$O$2:$O$301,19)),"")} | K23: {=IFERROR(INDEX(Alunos!$C:$C,SMALL(Alunos!$O$2:$O$301,19)),"")}
A24: {=IFERROR(INDEX(Boletos!$A:$A,SMALL(Boletos!$O$3:$O$3602,20)),"")} | B24: {=IFERROR(INDEX(Boletos!$B:$B,SMALL(Boletos!$O$3:$O$3602,20)),"")} | C24: {=IFERROR(INDEX(Boletos!$C:$C,SMALL(Boletos!$O$3:$O$3602,20)),"")} | D24: {=IFERROR(INDEX(Boletos!$D:$D,SMALL(Boletos!$O$3:$O$3602,20)),"")} | E24: {=IFERROR(INDEX(Boletos!$K:$K,SMALL(Boletos!$O$3:$O$3602,20)),"")} | F24: {=IFERROR(INDEX(Boletos!$L:$L,SMALL(Boletos!$O$3:$O$3602,20)),"")} | J24: {=IFERROR(INDEX(Alunos!$A:$A,SMALL(Alunos!$O$2:$O$301,20)),"")} | K24: {=IFERROR(INDEX(Alunos!$C:$C,SMALL(Alunos!$O$2:$O$301,20)),"")}
A25: {=IFERROR(INDEX(Boletos!$A:$A,SMALL(Boletos!$O$3:$O$3602,21)),"")} | B25: {=IFERROR(INDEX(Boletos!$B:$B,SMALL(Boletos!$O$3:$O$3602,21)),"")} | C25: {=IFERROR(INDEX(Boletos!$C:$C,SMALL(Boletos!$O$3:$O$3602,21)),"")} | D25: {=IFERROR(INDEX(Boletos!$D:$D,SMALL(Boletos!$O$3:$O$3602,21)),"")} | E25: {=IFERROR(INDEX(Boletos!$K:$K,SMALL(Boletos!$O$3:$O$3602,21)),"")} | F25: {=IFERROR(INDEX(Boletos!$L:$L,SMALL(Boletos!$O$3:$O$3602,21)),"")} | J25: {=IFERROR(INDEX(Alunos!$A:$A,SMALL(Alunos!$O$2:$O$301,21)),"")} | K25: {=IFERROR(INDEX(Alunos!$C:$C,SMALL(Alunos!$O$2:$O$301,21)),"")}
A26: {=IFERROR(INDEX(Boletos!$A:$A,SMALL(Boletos!$O$3:$O$3602,22)),"")} | B26: {=IFERROR(INDEX(Boletos!$B:$B,SMALL(Boletos!$O$3:$O$3602,22)),"")} | C26: {=IFERROR(INDEX(Boletos!$C:$C,SMALL(Boletos!$O$3:$O$3602,22)),"")} | D26: {=IFERROR(INDEX(Boletos!$D:$D,SMALL(Boletos!$O$3:$O$3602,22)),"")} | E26: {=IFERROR(INDEX(Boletos!$K:$K,SMALL(Boletos!$O$3:$O$3602,22)),"")} | F26: {=IFERROR(INDEX(Boletos!$L:$L,SMALL(Boletos!$O$3:$O$3602,22)),"")} | J26: {=IFERROR(INDEX(Alunos!$A:$A,SMALL(Alunos!$O$2:$O$301,22)),"")} | K26: {=IFERROR(INDEX(Alunos!$C:$C,SMALL(Alunos!$O$2:$O$301,22)),"")}
A27: {=IFERROR(INDEX(Boletos!$A:$A,SMALL(Boletos!$O$3:$O$3602,23)),"")} | B27: {=IFERROR(INDEX(Boletos!$B:$B,SMALL(Boletos!$O$3:$O$3602,23)),"")} | C27: {=IFERROR(INDEX(Boletos!$C:$C,SMALL(Boletos!$O$3:$O$3602,23)),"")} | D27: {=IFERROR(INDEX(Boletos!$D:$D,SMALL(Boletos!$O$3:$O$3602,23)),"")} | E27: {=IFERROR(INDEX(Boletos!$K:$K,SMALL(Boletos!$O$3:$O$3602,23)),"")} | F27: {=IFERROR(INDEX(Boletos!$L:$L,SMALL(Boletos!$O$3:$O$3602,23)),"")} | J27: {=IFERROR(INDEX(Alunos!$A:$A,SMALL(Alunos!$O$2:$O$301,23)),"")} | K27: {=IFERROR(INDEX(Alunos!$C:$C,SMALL(Alunos!$O$2:$O$301,23)),"")}
A28: {=IFERROR(INDEX(Boletos!$A:$A,SMALL(Boletos!$O$3:$O$3602,24)),"")} | B28: {=IFERROR(INDEX(Boletos!$B:$B,SMALL(Boletos!$O$3:$O$3602,24)),"")} | C28: {=IFERROR(INDEX(Boletos!$C:$C,SMALL(Boletos!$O$3:$O$3602,24)),"")} | D28: {=IFERROR(INDEX(Boletos!$D:$D,SMALL(Boletos!$O$3:$O$3602,24)),"")} | E28: {=IFERROR(INDEX(Boletos!$K:$K,SMALL(Boletos!$O$3:$O$3602,24)),"")} | F28: {=IFERROR(INDEX(Boletos!$L:$L,SMALL(Boletos!$O$3:$O$3602,24)),"")} | J28: {=IFERROR(INDEX(Alunos!$A:$A,SMALL(Alunos!$O$2:$O$301,24)),"")} | K28: {=IFERROR(INDEX(Alunos!$C:$C,SMALL(Alunos!$O$2:$O$301,24)),"")}
A29: {=IFERROR(INDEX(Boletos!$A:$A,SMALL(Boletos!$O$3:$O$3602,25)),"")} | B29: {=IFERROR(INDEX(Boletos!$B:$B,SMALL(Boletos!$O$3:$O$3602,25)),"")} | C29: {=IFERROR(INDEX(Boletos!$C:$C,SMALL(Boletos!$O$3:$O$3602,25)),"")} | D29: {=IFERROR(INDEX(Boletos!$D:$D,SMALL(Boletos!$O$3:$O$3602,25)),"")} | E29: {=IFERROR(INDEX(Boletos!$K:$K,SMALL(Boletos!$O$3:$O$3602,25)),"")} | F29: {=IFERROR(INDEX(Boletos!$L:$L,SMALL(Boletos!$O$3:$O$3602,25)),"")} | J29: {=IFERROR(INDEX(Alunos!$A:$A,SMALL(Alunos!$O$2:$O$301,25)),"")} | K29: {=IFERROR(INDEX(Alunos!$C:$C,SMALL(Alunos!$O$2:$O$301,25)),"")}
A30: {=IFERROR(INDEX(Boletos!$A:$A,SMALL(Boletos!$O$3:$O$3602,26)),"")} | B30: {=IFERROR(INDEX(Boletos!$B:$B,SMALL(Boletos!$O$3:$O$3602,26)),"")} | C30: {=IFERROR(INDEX(Boletos!$C:$C,SMALL(Boletos!$O$3:$O$3602,26)),"")} | D30: {=IFERROR(INDEX(Boletos!$D:$D,SMALL(Boletos!$O$3:$O$3602,26)),"")} | E30: {=IFERROR(INDEX(Boletos!$K:$K,SMALL(Boletos!$O$3:$O$3602,26)),"")} | F30: {=IFERROR(INDEX(Boletos!$L:$L,SMALL(Boletos!$O$3:$O$3602,26)),"")} | J30: {=IFERROR(INDEX(Alunos!$A:$A,SMALL(Alunos!$O$2:$O$301,26)),"")} | K30: {=IFERROR(INDEX(Alunos!$C:$C,SMALL(Alunos!$O$2:$O$301,26)),"")}
A31: {=IFERROR(INDEX(Boletos!$A:$A,SMALL(Boletos!$O$3:$O$3602,27)),"")} | B31: {=IFERROR(INDEX(Boletos!$B:$B,SMALL(Boletos!$O$3:$O$3602,27)),"")} | C31: {=IFERROR(INDEX(Boletos!$C:$C,SMALL(Boletos!$O$3:$O$3602,27)),"")} | D31: {=IFERROR(INDEX(Boletos!$D:$D,SMALL(Boletos!$O$3:$O$3602,27)),"")} | E31: {=IFERROR(INDEX(Boletos!$K:$K,SMALL(Boletos!$O$3:$O$3602,27)),"")} | F31: {=IFERROR(INDEX(Boletos!$L:$L,SMALL(Boletos!$O$3:$O$3602,27)),"")} | J31: {=IFERROR(INDEX(Alunos!$A:$A,SMALL(Alunos!$O$2:$O$301,27)),"")} | K31: {=IFERROR(INDEX(Alunos!$C:$C,SMALL(Alunos!$O$2:$O$301,27)),"")}
A32: {=IFERROR(INDEX(Boletos!$A:$A,SMALL(Boletos!$O$3:$O$3602,28)),"")} | B32: {=IFERROR(INDEX(Boletos!$B:$B,SMALL(Boletos!$O$3:$O$3602,28)),"")} | C32: {=IFERROR(INDEX(Boletos!$C:$C,SMALL(Boletos!$O$3:$O$3602,28)),"")} | D32: {=IFERROR(INDEX(Boletos!$D:$D,SMALL(Boletos!$O$3:$O$3602,28)),"")} | E32: {=IFERROR(INDEX(Boletos!$K:$K,SMALL(Boletos!$O$3:$O$3602,28)),"")} | F32: {=IFERROR(INDEX(Boletos!$L:$L,SMALL(Boletos!$O$3:$O$3602,28)),"")} | J32: {=IFERROR(INDEX(Alunos!$A:$A,SMALL(Alunos!$O$2:$O$301,28)),"")} | K32: {=IFERROR(INDEX(Alunos!$C:$C,SMALL(Alunos!$O$2:$O$301,28)),"")}
A33: {=IFERROR(INDEX(Boletos!$A:$A,SMALL(Boletos!$O$3:$O$3602,29)),"")} | B33: {=IFERROR(INDEX(Boletos!$B:$B,SMALL(Boletos!$O$3:$O$3602,29)),"")} | C33: {=IFERROR(INDEX(Boletos!$C:$C,SMALL(Boletos!$O$3:$O$3602,29)),"")} | D33: {=IFERROR(INDEX(Boletos!$D:$D,SMALL(Boletos!$O$3:$O$3602,29)),"")} | E33: {=IFERROR(INDEX(Boletos!$K:$K,SMALL(Boletos!$O$3:$O$3602,29)),"")} | F33: {=IFERROR(INDEX(Boletos!$L:$L,SMALL(Boletos!$O$3:$O$3602,29)),"")} | J33: {=IFERROR(INDEX(Alunos!$A:$A,SMALL(Alunos!$O$2:$O$301,29)),"")} | K33: {=IFERROR(INDEX(Alunos!$C:$C,SMALL(Alunos!$O$2:$O$301,29)),"")}
A34: {=IFERROR(INDEX(Boletos!$A:$A,SMALL(Boletos!$O$3:$O$3602,30)),"")} | B34: {=IFERROR(INDEX(Boletos!$B:$B,SMALL(Boletos!$O$3:$O$3602,30)),"")} | C34: {=IFERROR(INDEX(Boletos!$C:$C,SMALL(Boletos!$O$3:$O$3602,30)),"")} | D34: {=IFERROR(INDEX(Boletos!$D:$D,SMALL(Boletos!$O$3:$O$3602,30)),"")} | E34: {=IFERROR(INDEX(Boletos!$K:$K,SMALL(Boletos!$O$3:$O$3602,30)),"")} | F34: {=IFERROR(INDEX(Boletos!$L:$L,SMALL(Boletos!$O$3:$O$3602,30)),"")} | J34: {=IFERROR(INDEX(Alunos!$A:$A,SMALL(Alunos!$O$2:$O$301,30)),"")} | K34: {=IFERROR(INDEX(Alunos!$C:$C,SMALL(Alunos!$O$2:$O$301,30)),"")}
A35: {=IFERROR(INDEX(Boletos!$A:$A,SMALL(Boletos!$O$3:$O$3602,31)),"")} | B35: {=IFERROR(INDEX(Boletos!$B:$B,SMALL(Boletos!$O$3:$O$3602,31)),"")} | C35: {=IFERROR(INDEX(Boletos!$C:$C,SMALL(Boletos!$O$3:$O$3602,31)),"")} | D35: {=IFERROR(INDEX(Boletos!$D:$D,SMALL(Boletos!$O$3:$O$3602,31)),"")} | E35: {=IFERROR(INDEX(Boletos!$K:$K,SMALL(Boletos!$O$3:$O$3602,31)),"")} | F35: {=IFERROR(INDEX(Boletos!$L:$L,SMALL(Boletos!$O$3:$O$3602,31)),"")} | J35: {=IFERROR(INDEX(Alunos!$A:$A,SMALL(Alunos!$O$2:$O$301,31)),"")} | K35: {=IFERROR(INDEX(Alunos!$C:$C,SMALL(Alunos!$O$2:$O$301,31)),"")}
A36: {=IFERROR(INDEX(Boletos!$A:$A,SMALL(Boletos!$O$3:$O$3602,32)),"")} | B36: {=IFERROR(INDEX(Boletos!$B:$B,SMALL(Boletos!$O$3:$O$3602,32)),"")} | C36: {=IFERROR(INDEX(Boletos!$C:$C,SMALL(Boletos!$O$3:$O$3602,32)),"")} | D36: {=IFERROR(INDEX(Boletos!$D:$D,SMALL(Boletos!$O$3:$O$3602,32)),"")} | E36: {=IFERROR(INDEX(Boletos!$K:$K,SMALL(Boletos!$O$3:$O$3602,32)),"")} | F36: {=IFERROR(INDEX(Boletos!$L:$L,SMALL(Boletos!$O$3:$O$3602,32)),"")} | J36: {=IFERROR(INDEX(Alunos!$A:$A,SMALL(Alunos!$O$2:$O$301,32)),"")} | K36: {=IFERROR(INDEX(Alunos!$C:$C,SMALL(Alunos!$O$2:$O$301,32)),"")}
A37: {=IFERROR(INDEX(Boletos!$A:$A,SMALL(Boletos!$O$3:$O$3602,33)),"")} | B37: {=IFERROR(INDEX(Boletos!$B:$B,SMALL(Boletos!$O$3:$O$3602,33)),"")} | C37: {=IFERROR(INDEX(Boletos!$C:$C,SMALL(Boletos!$O$3:$O$3602,33)),"")} | D37: {=IFERROR(INDEX(Boletos!$D:$D,SMALL(Boletos!$O$3:$O$3602,33)),"")} | E37: {=IFERROR(INDEX(Boletos!$K:$K,SMALL(Boletos!$O$3:$O$3602,33)),"")} | F37: {=IFERROR(INDEX(Boletos!$L:$L,SMALL(Boletos!$O$3:$O$3602,33)),"")} | J37: {=IFERROR(INDEX(Alunos!$A:$A,SMALL(Alunos!$O$2:$O$301,33)),"")} | K37: {=IFERROR(INDEX(Alunos!$C:$C,SMALL(Alunos!$O$2:$O$301,33)),"")}
A38: {=IFERROR(INDEX(Boletos!$A:$A,SMALL(Boletos!$O$3:$O$3602,34)),"")} | B38: {=IFERROR(INDEX(Boletos!$B:$B,SMALL(Boletos!$O$3:$O$3602,34)),"")} | C38: {=IFERROR(INDEX(Boletos!$C:$C,SMALL(Boletos!$O$3:$O$3602,34)),"")} | D38: {=IFERROR(INDEX(Boletos!$D:$D,SMALL(Boletos!$O$3:$O$3602,34)),"")} | E38: {=IFERROR(INDEX(Boletos!$K:$K,SMALL(Boletos!$O$3:$O$3602,34)),"")} | F38: {=IFERROR(INDEX(Boletos!$L:$L,SMALL(Boletos!$O$3:$O$3602,34)),"")} | J38: {=IFERROR(INDEX(Alunos!$A:$A,SMALL(Alunos!$O$2:$O$301,34)),"")} | K38: {=IFERROR(INDEX(Alunos!$C:$C,SMALL(Alunos!$O$2:$O$301,34)),"")}
A39: {=IFERROR(INDEX(Boletos!$A:$A,SMALL(Boletos!$O$3:$O$3602,35)),"")} | B39: {=IFERROR(INDEX(Boletos!$B:$B,SMALL(Boletos!$O$3:$O$3602,35)),"")} | C39: {=IFERROR(INDEX(Boletos!$C:$C,SMALL(Boletos!$O$3:$O$3602,35)),"")} | D39: {=IFERROR(INDEX(Boletos!$D:$D,SMALL(Boletos!$O$3:$O$3602,35)),"")} | E39: {=IFERROR(INDEX(Boletos!$K:$K,SMALL(Boletos!$O$3:$O$3602,35)),"")} | F39: {=IFERROR(INDEX(Boletos!$L:$L,SMALL(Boletos!$O$3:$O$3602,35)),"")} | J39: {=IFERROR(INDEX(Alunos!$A:$A,SMALL(Alunos!$O$2:$O$301,35)),"")} | K39: {=IFERROR(INDEX(Alunos!$C:$C,SMALL(Alunos!$O$2:$O$301,35)),"")}
A40: {=IFERROR(INDEX(Boletos!$A:$A,SMALL(Boletos!$O$3:$O$3602,36)),"")} | B40: {=IFERROR(INDEX(Boletos!$B:$B,SMALL(Boletos!$O$3:$O$3602,36)),"")} | C40: {=IFERROR(INDEX(Boletos!$C:$C,SMALL(Boletos!$O$3:$O$3602,36)),"")} | D40: {=IFERROR(INDEX(Boletos!$D:$D,SMALL(Boletos!$O$3:$O$3602,36)),"")} | E40: {=IFERROR(INDEX(Boletos!$K:$K,SMALL(Boletos!$O$3:$O$3602,36)),"")} | F40: {=IFERROR(INDEX(Boletos!$L:$L,SMALL(Boletos!$O$3:$O$3602,36)),"")} | J40: {=IFERROR(INDEX(Alunos!$A:$A,SMALL(Alunos!$O$2:$O$301,36)),"")} | K40: {=IFERROR(INDEX(Alunos!$C:$C,SMALL(Alunos!$O$2:$O$301,36)),"")}
A41: {=IFERROR(INDEX(Boletos!$A:$A,SMALL(Boletos!$O$3:$O$3602,37)),"")} | B41: {=IFERROR(INDEX(Boletos!$B:$B,SMALL(Boletos!$O$3:$O$3602,37)),"")} | C41: {=IFERROR(INDEX(Boletos!$C:$C,SMALL(Boletos!$O$3:$O$3602,37)),"")} | D41: {=IFERROR(INDEX(Boletos!$D:$D,SMALL(Boletos!$O$3:$O$3602,37)),"")} | E41: {=IFERROR(INDEX(Boletos!$K:$K,SMALL(Boletos!$O$3:$O$3602,37)),"")} | F41: {=IFERROR(INDEX(Boletos!$L:$L,SMALL(Boletos!$O$3:$O$3602,37)),"")} | J41: {=IFERROR(INDEX(Alunos!$A:$A,SMALL(Alunos!$O$2:$O$301,37)),"")} | K41: {=IFERROR(INDEX(Alunos!$C:$C,SMALL(Alunos!$O$2:$O$301,37)),"")}
...

Sheet Config
A1: ="CONFIGURAÇÕES DA ESCOLA – "&B4
A2: Legenda: células em bege = você preenche. Texto preto = calcula sozinho.
A3: Nome da escola | B3: Escola Modelo (dados fictícios)
A4: Ano letivo | B4: 2026
A5: Dia de vencimento do boleto | B5: 10
A6: Multa por atraso | B6: 0.02 | D6: Multa máxima permitida em mensalidade: 2%
A7: Juros ao mês | B7: 0.01
A8: Tarifa por boleto pago | B8: 2.49 | D8: Confira a tarifa real no contrato da plataforma de cobrança / banco
A9: ="Saldo inicial do caixa (01/01/"&B4&")" | B9: 6000
A10: Plataforma de cobrança | B10: Plataforma de boletos
A12: ="Turmas e mensalidades "&B4 | D12: Atividades extras (mensal)
A13: Turma | B13: Mensalidade | D13: Atividade | E13: Valor mensal
A14: Maternal 2 | B14: 620 | D14: Judô | E14: 110
A15: Maternal 3 | B15: 640 | D15: Balé | E15: 120
A16: 1º Período | B16: 690
A17: 2º Período | B17: 710
A20: Categorias de despesa | D20: Categorias de receita
A21: Salários | D21: Matrícula
A22: Encargos | D22: Rematrícula
A23: Aluguel | D23: Material didático
A24: Energia | D24: Uniforme
A25: Água | D25: Eventos e festas
A26: Internet | D26: Passeios
A27: Material | D27: Cantina
A28: Manutenção | D28: Horário estendido
A29: Impostos | D29: Taxas e documentos
A30: Marketing | D30: Doações
A31: Tarifas bancárias | D31: Outros
A32: Outros
A36: Você pode adicionar categorias nas linhas vazias – elas aparecem nas listas sozinhas.

Sheet Alunos
A1: Nome do aluno | B1: Turma | C1: Responsável financeiro | D1: CPF do responsável | E1: Telefone | F1: Mensalidade | G1: Judô? | H1: Balé? | I1: Valor atividades | J1: Desconto (%) | K1: Valor do boleto | L1: Situação | M1: Mês de entrada | N1: Mês de saída | R1: Cadastre alunos novos na primeira linha vazia. Não reordene esta aba – a lista em ordem alfabética fica na aba Alunos A-Z.
A2: Laura Holanda (fictício) | B2: Maternal 2 | C2: Érica Holanda | E2: (00) 99133-9711 | F2: {=IF(B2="","",IFERROR(INDEX(Config!$B$14:$B$17,MATCH(B2,Config!$A$14:$A$17,0)),0))} | G2: Não | H2: Não | I2: =IF(A2="","",IF(G2="Sim",Config!$E$14,0)+IF(H2="Sim",Config!$E$15,0)) | K2: =IF(OR(A2="",L2="Inativo"),"",N(F2)*(1-N(J2))+N(I2)) | L2: Ativo | O2: =IF(AND(A2<>"",D2=""),ROW(),"") | P2: =IF(A2="","",COUNTIF($A$2:$A$301,"<"&A2)+COUNTIF($A$2:A2,A2))
A3: Gael Rezende (fictício) | B3: Maternal 3 | C3: Leandro Rezende | D3: ***.585.813-** | E3: (00) 92064-1994 | F3: {=IF(B3="","",IFERROR(INDEX(Config!$B$14:$B$17,MATCH(B3,Config!$A$14:$A$17,0)),0))} | G3: Não | H3: Não | I3: =IF(A3="","",IF(G3="Sim",Config!$E$14,0)+IF(H3="Sim",Config!$E$15,0)) | K3: =IF(OR(A3="",L3="Inativo"),"",N(F3)*(1-N(J3))+N(I3)) | L3: Ativo | O3: =IF(AND(A3<>"",D3=""),ROW(),"") | P3: =IF(A3="","",COUNTIF($A$2:$A$301,"<"&A3)+COUNTIF($A$2:A3,A3))
A4: Cecília Duarte (fictício) | B4: 1º Período | C4: Renata Duarte | D4: ***.240.938-** | E4: (00) 98053-5561 | F4: {=IF(B4="","",IFERROR(INDEX(Config!$B$14:$B$17,MATCH(B4,Config!$A$14:$A$17,0)),0))} | G4: Não | H4: Não | I4: =IF(A4="","",IF(G4="Sim",Config!$E$14,0)+IF(H4="Sim",Config!$E$15,0)) | K4: =IF(OR(A4="",L4="Inativo"),"",N(F4)*(1-N(J4))+N(I4)) | L4: Ativo | O4: =IF(AND(A4<>"",D4=""),ROW(),"") | P4: =IF(A4="","",COUNTIF($A$2:$A$301,"<"&A4)+COUNTIF($A$2:A4,A4))
A5: Elisa Esteves (fictício) | B5: 2º Período | C5: Zilda Esteves | D5: ***.593.749-** | E5: (00) 97560-2019 | F5: {=IF(B5="","",IFERROR(INDEX(Config!$B$14:$B$17,MATCH(B5,Config!$A$14:$A$17,0)),0))} | G5: Sim | H5: Não | I5: =IF(A5="","",IF(G5="Sim",Config!$E$14,0)+IF(H5="Sim",Config!$E$15,0)) | K5: =IF(OR(A5="",L5="Inativo"),"",N(F5)*(1-N(J5))+N(I5)) | L5: Ativo | O5: =IF(AND(A5<>"",D5=""),ROW(),"") | P5: =IF(A5="","",COUNTIF($A$2:$A$301,"<"&A5)+COUNTIF($A$2:A5,A5))
A6: Heitor Prado (fictício) | B6: Maternal 2 | C6: Fábio Prado | D6: ***.699.564-** | E6: (00) 96924-5911 | F6: {=IF(B6="","",IFERROR(INDEX(Config!$B$14:$B$17,MATCH(B6,Config!$A$14:$A$17,0)),0))} | G6: Sim | H6: Sim | I6: =IF(A6="","",IF(G6="Sim",Config!$E$14,0)+IF(H6="Sim",Config!$E$15,0)) | K6: =IF(OR(A6="",L6="Inativo"),"",N(F6)*(1-N(J6))+N(I6)) | L6: Ativo | O6: =IF(AND(A6<>"",D6=""),ROW(),"") | P6: =IF(A6="","",COUNTIF($A$2:$A$301,"<"&A6)+COUNTIF($A$2:A6,A6))
A7: Samuel Macedo (fictício) | B7: 1º Período | C7: Paulo Macedo | D7: ***.992.608-** | E7: (00) 92320-3725 | F7: {=IF(B7="","",IFERROR(INDEX(Config!$B$14:$B$17,MATCH(B7,Config!$A$14:$A$17,0)),0))} | G7: Não | H7: Não | I7: =IF(A7="","",IF(G7="Sim",Config!$E$14,0)+IF(H7="Sim",Config!$E$15,0)) | K7: =IF(OR(A7="",L7="Inativo"),"",N(F7)*(1-N(J7))+N(I7)) | L7: Ativo | O7: =IF(AND(A7<>"",D7=""),ROW(),"") | P7: =IF(A7="","",COUNTIF($A$2:$A$301,"<"&A7)+COUNTIF($A$2:A7,A7))
A8: Valentina Zanetti (fictício) | B8: Maternal 3 | C8: Gisele Zanetti | D8: ***.898.349-** | E8: (00) 92341-5919 | F8: {=IF(B8="","",IFERROR(INDEX(Config!$B$14:$B$17,MATCH(B8,Config!$A$14:$A$17,0)),0))} | G8: Não | H8: Não | I8: =IF(A8="","",IF(G8="Sim",Config!$E$14,0)+IF(H8="Sim",Config!$E$15,0)) | K8: =IF(OR(A8="",L8="Inativo"),"",N(F8)*(1-N(J8))+N(I8)) | L8: Ativo | O8: =IF(AND(A8<>"",D8=""),ROW(),"") | P8: =IF(A8="","",COUNTIF($A$2:$A$301,"<"&A8)+COUNTIF($A$2:A8,A8))
A9: Sophia Ornelas (fictício) | B9: Maternal 3 | C9: Karen Ornelas | D9: ***.693.916-** | E9: (00) 98474-2126 | F9: {=IF(B9="","",IFERROR(INDEX(Config!$B$14:$B$17,MATCH(B9,Config!$A$14:$A$17,0)),0))} | G9: Não | H9: Não | I9: =IF(A9="","",IF(G9="Sim",Config!$E$14,0)+IF(H9="Sim",Config!$E$15,0)) | K9: =IF(OR(A9="",L9="Inativo"),"",N(F9)*(1-N(J9))+N(I9)) | L9: Ativo | O9: =IF(AND(A9<>"",D9=""),ROW(),"") | P9: =IF(A9="","",COUNTIF($A$2:$A$301,"<"&A9)+COUNTIF($A$2:A9,A9))
A10: Pedro Barros (fictício) | B10: 1º Período | C10: Vítor Barros | D10: ***.369.388-** | E10: (00) 91067-3386 | F10: {=IF(B10="","",IFERROR(INDEX(Config!$B$14:$B$17,MATCH(B10,Config!$A$14:$A$17,0)),0))} | G10: Não | H10: Não | I10: =IF(A10="","",IF(G10="Sim",Config!$E$14,0)+IF(H10="Sim",Config!$E$15,0)) | K10: =IF(OR(A10="",L10="Inativo"),"",N(F10)*(1-N(J10))+N(I10)) | L10: Ativo | O10: =IF(AND(A10<>"",D10=""),ROW(),"") | P10: =IF(A10="","",COUNTIF($A$2:$A$301,"<"&A10)+COUNTIF($A$2:A10,A10))
A11: Lívia Jardim (fictício) | B11: 1º Período | C11: Olívia Jardim | D11: ***.160.323-** | E11: (00) 95709-3119 | F11: {=IF(B11="","",IFERROR(INDEX(Config!$B$14:$B$17,MATCH(B11,Config!$A$14:$A$17,0)),0))} | G11: Não | H11: Não | I11: =IF(A11="","",IF(G11="Sim",Config!$E$14,0)+IF(H11="Sim",Config!$E$15,0)) | K11: =IF(OR(A11="",L11="Inativo"),"",N(F11)*(1-N(J11))+N(I11)) | L11: Ativo | O11: =IF(AND(A11<>"",D11=""),ROW(),"") | P11: =IF(A11="","",COUNTIF($A$2:$A$301,"<"&A11)+COUNTIF($A$2:A11,A11))
A12: Isabela Ibiapina (fictício) | B12: Maternal 3 | C12: Marta Ibiapina | D12: ***.691.797-** | E12: (00) 98301-5662 | F12: {=IF(B12="","",IFERROR(INDEX(Config!$B$14:$B$17,MATCH(B12,Config!$A$14:$A$17,0)),0))} | G12: Não | H12: Não | I12: =IF(A12="","",IF(G12="Sim",Config!$E$14,0)+IF(H12="Sim",Config!$E$15,0)) | K12: =IF(OR(A12="",L12="Inativo"),"",N(F12)*(1-N(J12))+N(I12)) | L12: Ativo | O12: =IF(AND(A12<>"",D12=""),ROW(),"") | P12: =IF(A12="","",COUNTIF($A$2:$A$301,"<"&A12)+COUNTIF($A$2:A12,A12))
A13: Gabriel Nogueira (fictício) | B13: 2º Período | C13: Yuri Nogueira | D13: ***.857.155-** | E13: (00) 98481-7428 | F13: {=IF(B13="","",IFERROR(INDEX(Config!$B$14:$B$17,MATCH(B13,Config!$A$14:$A$17,0)),0))} | G13: Não | H13: Não | I13: =IF(A13="","",IF(G13="Sim",Config!$E$14,0)+IF(H13="Sim",Config!$E$15,0)) | K13: =IF(OR(A13="",L13="Inativo"),"",N(F13)*(1-N(J13))+N(I13)) | L13: Ativo | M13: Mar | O13: =IF(AND(A13<>"",D13=""),ROW(),"") | P13: =IF(A13="","",COUNTIF($A$2:$A$301,"<"&A13)+COUNTIF($A$2:A13,A13))
A14: Miguel Teles (fictício) | B14: Maternal 2 | C14: Bruno Teles | D14: ***.670.979-** | E14: (00) 93181-5744 | F14: {=IF(B14="","",IFERROR(INDEX(Config!$B$14:$B$17,MATCH(B14,Config!$A$14:$A$17,0)),0))} | G14: Não | H14: Não | I14: =IF(A14="","",IF(G14="Sim",Config!$E$14,0)+IF(H14="Sim",Config!$E$15,0)) | K14: =IF(OR(A14="",L14="Inativo"),"",N(F14)*(1-N(J14))+N(I14)) | L14: Ativo | O14: =IF(AND(A14<>"",D14=""),ROW(),"") | P14: =IF(A14="","",COUNTIF($A$2:$A$301,"<"&A14)+COUNTIF($A$2:A14,A14))
A15: Alice Farias (fictício) | B15: Maternal 2 | C15: Ana Farias | D15: ***.328.745-** | E15: (00) 92013-7499 | F15: {=IF(B15="","",IFERROR(INDEX(Config!$B$14:$B$17,MATCH(B15,Config!$A$14:$A$17,0)),0))} | G15: Sim | H15: Sim | I15: =IF(A15="","",IF(G15="Sim",Config!$E$14,0)+IF(H15="Sim",Config!$E$15,0)) | K15: =IF(OR(A15="",L15="Inativo"),"",N(F15)*(1-N(J15))+N(I15)) | L15: Ativo | O15: =IF(AND(A15<>"",D15=""),ROW(),"") | P15: =IF(A15="","",COUNTIF($A$2:$A$301,"<"&A15)+COUNTIF($A$2:A15,A15))
A16: Davi Uchôa (fictício) | B16: Maternal 3 | C16: João Uchôa | D16: ***.179.882-** | E16: (00) 96140-6572 | F16: {=IF(B16="","",IFERROR(INDEX(Config!$B$14:$B$17,MATCH(B16,Config!$A$14:$A$17,0)),0))} | G16: Não | H16: Não | I16: =IF(A16="","",IF(G16="Sim",Config!$E$14,0)+IF(H16="Sim",Config!$E$15,0)) | J16: 0.1 | K16: =IF(OR(A16="",L16="Inativo"),"",N(F16)*(1-N(J16))+N(I16)) | L16: Ativo | O16: =IF(AND(A16<>"",D16=""),ROW(),"") | P16: =IF(A16="","",COUNTIF($A$2:$A$301,"<"&A16)+COUNTIF($A$2:A16,A16))
A17: Arthur Queiroz (fictício) | B17: Maternal 2 | C17: Diego Queiroz | D17: ***.481.199-** | E17: (00) 99974-2028 | F17: {=IF(B17="","",IFERROR(INDEX(Config!$B$14:$B$17,MATCH(B17,Config!$A$14:$A$17,0)),0))} | G17: Não | H17: Não | I17: =IF(A17="","",IF(G17="Sim",Config!$E$14,0)+IF(H17="Sim",Config!$E$15,0)) | K17: =IF(OR(A17="",L17="Inativo"),"",N(F17)*(1-N(J17))+N(I17)) | L17: Ativo | O17: =IF(AND(A17<>"",D17=""),ROW(),"") | P17: =IF(A17="","",COUNTIF($A$2:$A$301,"<"&A17)+COUNTIF($A$2:A17,A17))
A18: Theo Xavier (fictício) | B18: Maternal 3 | C18: Henrique Xavier | D18: ***.846.559-** | E18: (00) 95717-2199 | F18: {=IF(B18="","",IFERROR(INDEX(Config!$B$14:$B$17,MATCH(B18,Config!$A$14:$A$17,0)),0))} | G18: Sim | H18: Não | I18: =IF(A18="","",IF(G18="Sim",Config!$E$14,0)+IF(H18="Sim",Config!$E$15,0)) | K18: =IF(OR(A18="",L18="Inativo"),"",N(F18)*(1-N(J18))+N(I18)) | L18: Ativo | O18: =IF(AND(A18<>"",D18=""),ROW(),"") | P18: =IF(A18="","",COUNTIF($A$2:$A$301,"<"&A18)+COUNTIF($A$2:A18,A18))
A19: Luna Vasconcelos (fictício) | B19: 2º Período | C19: Wanda Vasconcelos | D19: ***.679.426-** | E19: (00) 93056-9445 | F19: {=IF(B19="","",IFERROR(INDEX(Config!$B$14:$B$17,MATCH(B19,Config!$A$14:$A$17,0)),0))} | G19: Não | H19: Não | I19: =IF(A19="","",IF(G19="Sim",Config!$E$14,0)+IF(H19="Sim",Config!$E$15,0)) | K19: =IF(OR(A19="",L19="Inativo"),"",N(F19)*(1-N(J19))+N(I19)) | L19: Ativo | O19: =IF(AND(A19<>"",D19=""),ROW(),"") | P19: =IF(A19="","",COUNTIF($A$2:$A$301,"<"&A19)+COUNTIF($A$2:A19,A19))
A20: Maitê Cardoso (fictício) | B20: 1º Período | C20: Tatiane Cardoso | D20: ***.337.774-** | E20: (00) 94822-1197 | F20: {=IF(B20="","",IFERROR(INDEX(Config!$B$14:$B$17,MATCH(B20,Config!$A$14:$A$17,0)),0))} | G20: Não | H20: Não | I20: =IF(A20="","",IF(G20="Sim",Config!$E$14,0)+IF(H20="Sim",Config!$E$15,0)) | K20: =IF(OR(A20="",L20="Inativo"),"",N(F20)*(1-N(J20))+N(I20)) | L20: Ativo | O20: =IF(AND(A20<>"",D20=""),ROW(),"") | P20: =IF(A20="","",COUNTIF($A$2:$A$301,"<"&A20)+COUNTIF($A$2:A20,A20))
A21: Lucas Sales (fictício) | B21: 1º Período | C21: Sérgio Sales | E21: (00) 97233-4780 | F21: {=IF(B21="","",IFERROR(INDEX(Config!$B$14:$B$17,MATCH(B21,Config!$A$14:$A$17,0)),0))} | G21: Sim | H21: Sim | I21: =IF(A21="","",IF(G21="Sim",Config!$E$14,0)+IF(H21="Sim",Config!$E$15,0)) | K21: =IF(OR(A21="",L21="Inativo"),"",N(F21)*(1-N(J21))+N(I21)) | L21: Ativo | O21: =IF(AND(A21<>"",D21=""),ROW(),"") | P21: =IF(A21="","",COUNTIF($A$2:$A$301,"<"&A21)+COUNTIF($A$2:A21,A21))
A22: Helena Yamada (fictício) | B22: Maternal 2 | C22: Carla Yamada | D22: ***.684.415-** | E22: (00) 93961-2688 | F22: {=IF(B22="","",IFERROR(INDEX(Config!$B$14:$B$17,MATCH(B22,Config!$A$14:$A$17,0)),0))} | G22: Não | H22: Não | I22: =IF(A22="","",IF(G22="Sim",Config!$E$14,0)+IF(H22="Sim",Config!$E$15,0)) | K22: =IF(OR(A22="",L22="Inativo"),"",N(F22)*(1-N(J22))+N(I22)) | L22: Bolsista | O22: =IF(AND(A22<>"",D22=""),ROW(),"") | P22: =IF(A22="","",COUNTIF($A$2:$A$301,"<"&A22)+COUNTIF($A$2:A22,A22))
A23: Rafael Leal (fictício) | B23: 2º Período | C23: Márcio Leal | D23: ***.551.266-** | E23: (00) 92801-6571 | F23: {=IF(B23="","",IFERROR(INDEX(Config!$B$14:$B$17,MATCH(B23,Config!$A$14:$A$17,0)),0))} | G23: Não | H23: Sim | I23: =IF(A23="","",IF(G23="Sim",Config!$E$14,0)+IF(H23="Sim",Config!$E$15,0)) | K23: =IF(OR(A23="",L23="Inativo"),"",N(F23)*(1-N(J23))+N(I23)) | L23: Ativo | O23: =IF(AND(A23<>"",D23=""),ROW(),"") | P23: =IF(A23="","",COUNTIF($A$2:$A$301,"<"&A23)+COUNTIF($A$2:A23,A23))
A24: Manuela Gomes (fictício) | B24: Maternal 3 | C24: Ingrid Gomes | D24: ***.875.450-** | E24: (00) 93490-9011 | F24: {=IF(B24="","",IFERROR(INDEX(Config!$B$14:$B$17,MATCH(B24,Config!$A$14:$A$17,0)),0))} | G24: Não | H24: Não | I24: =IF(A24="","",IF(G24="Sim",Config!$E$14,0)+IF(H24="Sim",Config!$E$15,0)) | J24: 0.1 | K24: =IF(OR(A24="",L24="Inativo"),"",N(F24)*(1-N(J24))+N(I24)) | L24: Ativo | O24: =IF(AND(A24<>"",D24=""),ROW(),"") | P24: =IF(A24="","",COUNTIF($A$2:$A$301,"<"&A24)+COUNTIF($A$2:A24,A24))
A25: Bernardo Almeida (fictício) | B25: Maternal 3 | C25: Nelson Almeida | D25: ***.455.123-** | E25: (00) 98564-6823 | F25: {=IF(B25="","",IFERROR(INDEX(Config!$B$14:$B$17,MATCH(B25,Config!$A$14:$A$17,0)),0))} | G25: Sim | H25: Sim | I25: =IF(A25="","",IF(G25="Sim",Config!$E$14,0)+IF(H25="Sim",Config!$E$15,0)) | K25: =IF(OR(A25="",L25="Inativo"),"",N(F25)*(1-N(J25))+N(I25)) | L25: Ativo | N25: Jun | O25: =IF(AND(A25<>"",D25=""),ROW(),"") | P25: =IF(A25="","",COUNTIF($A$2:$A$301,"<"&A25)+COUNTIF($A$2:A25,A25))
F26: {=IF(B26="","",IFERROR(INDEX(Config!$B$14:$B$17,MATCH(B26,Config!$A$14:$A$17,0)),0))} | I26: =IF(A26="","",IF(G26="Sim",Config!$E$14,0)+IF(H26="Sim",Config!$E$15,0)) | K26: =IF(OR(A26="",L26="Inativo"),"",N(F26)*(1-N(J26))+N(I26)) | O26: =IF(AND(A26<>"",D26=""),ROW(),"") | P26: =IF(A26="","",COUNTIF($A$2:$A$301,"<"&A26)+COUNTIF($A$2:A26,A26))
F27: {=IF(B27="","",IFERROR(INDEX(Config!$B$14:$B$17,MATCH(B27,Config!$A$14:$A$17,0)),0))} | I27: =IF(A27="","",IF(G27="Sim",Config!$E$14,0)+IF(H27="Sim",Config!$E$15,0)) | K27: =IF(OR(A27="",L27="Inativo"),"",N(F27)*(1-N(J27))+N(I27)) | O27: =IF(AND(A27<>"",D27=""),ROW(),"") | P27: =IF(A27="","",COUNTIF($A$2:$A$301,"<"&A27)+COUNTIF($A$2:A27,A27))
F28: {=IF(B28="","",IFERROR(INDEX(Config!$B$14:$B$17,MATCH(B28,Config!$A$14:$A$17,0)),0))} | I28: =IF(A28="","",IF(G28="Sim",Config!$E$14,0)+IF(H28="Sim",Config!$E$15,0)) | K28: =IF(OR(A28="",L28="Inativo"),"",N(F28)*(1-N(J28))+N(I28)) | O28: =IF(AND(A28<>"",D28=""),ROW(),"") | P28: =IF(A28="","",COUNTIF($A$2:$A$301,"<"&A28)+COUNTIF($A$2:A28,A28))
F29: {=IF(B29="","",IFERROR(INDEX(Config!$B$14:$B$17,MATCH(B29,Config!$A$14:$A$17,0)),0))} | I29: =IF(A29="","",IF(G29="Sim",Config!$E$14,0)+IF(H29="Sim",Config!$E$15,0)) | K29: =IF(OR(A29="",L29="Inativo"),"",N(F29)*(1-N(J29))+N(I29)) | O29: =IF(AND(A29<>"",D29=""),ROW(),"") | P29: =IF(A29="","",COUNTIF($A$2:$A$301,"<"&A29)+COUNTIF($A$2:A29,A29))
F30: {=IF(B30="","",IFERROR(INDEX(Config!$B$14:$B$17,MATCH(B30,Config!$A$14:$A$17,0)),0))} | I30: =IF(A30="","",IF(G30="Sim",Config!$E$14,0)+IF(H30="Sim",Config!$E$15,0)) | K30: =IF(OR(A30="",L30="Inativo"),"",N(F30)*(1-N(J30))+N(I30)) | O30: =IF(AND(A30<>"",D30=""),ROW(),"") | P30: =IF(A30="","",COUNTIF($A$2:$A$301,"<"&A30)+COUNTIF($A$2:A30,A30))
F31: {=IF(B31="","",IFERROR(INDEX(Config!$B$14:$B$17,MATCH(B31,Config!$A$14:$A$17,0)),0))} | I31: =IF(A31="","",IF(G31="Sim",Config!$E$14,0)+IF(H31="Sim",Config!$E$15,0)) | K31: =IF(OR(A31="",L31="Inativo"),"",N(F31)*(1-N(J31))+N(I31)) | O31: =IF(AND(A31<>"",D31=""),ROW(),"") | P31: =IF(A31="","",COUNTIF($A$2:$A$301,"<"&A31)+COUNTIF($A$2:A31,A31))
F32: {=IF(B32="","",IFERROR(INDEX(Config!$B$14:$B$17,MATCH(B32,Config!$A$14:$A$17,0)),0))} | I32: =IF(A32="","",IF(G32="Sim",Config!$E$14,0)+IF(H32="Sim",Config!$E$15,0)) | K32: =IF(OR(A32="",L32="Inativo"),"",N(F32)*(1-N(J32))+N(I32)) | O32: =IF(AND(A32<>"",D32=""),ROW(),"") | P32: =IF(A32="","",COUNTIF($A$2:$A$301,"<"&A32)+COUNTIF($A$2:A32,A32))
F33: {=IF(B33="","",IFERROR(INDEX(Config!$B$14:$B$17,MATCH(B33,Config!$A$14:$A$17,0)),0))} | I33: =IF(A33="","",IF(G33="Sim",Config!$E$14,0)+IF(H33="Sim",Config!$E$15,0)) | K33: =IF(OR(A33="",L33="Inativo"),"",N(F33)*(1-N(J33))+N(I33)) | O33: =IF(AND(A33<>"",D33=""),ROW(),"") | P33: =IF(A33="","",COUNTIF($A$2:$A$301,"<"&A33)+COUNTIF($A$2:A33,A33))
F34: {=IF(B34="","",IFERROR(INDEX(Config!$B$14:$B$17,MATCH(B34,Config!$A$14:$A$17,0)),0))} | I34: =IF(A34="","",IF(G34="Sim",Config!$E$14,0)+IF(H34="Sim",Config!$E$15,0)) | K34: =IF(OR(A34="",L34="Inativo"),"",N(F34)*(1-N(J34))+N(I34)) | O34: =IF(AND(A34<>"",D34=""),ROW(),"") | P34: =IF(A34="","",COUNTIF($A$2:$A$301,"<"&A34)+COUNTIF($A$2:A34,A34))
F35: {=IF(B35="","",IFERROR(INDEX(Config!$B$14:$B$17,MATCH(B35,Config!$A$14:$A$17,0)),0))} | I35: =IF(A35="","",IF(G35="Sim",Config!$E$14,0)+IF(H35="Sim",Config!$E$15,0)) | K35: =IF(OR(A35="",L35="Inativo"),"",N(F35)*(1-N(J35))+N(I35)) | O35: =IF(AND(A35<>"",D35=""),ROW(),"") | P35: =IF(A35="","",COUNTIF($A$2:$A$301,"<"&A35)+COUNTIF($A$2:A35,A35))
F36: {=IF(B36="","",IFERROR(INDEX(Config!$B$14:$B$17,MATCH(B36,Config!$A$14:$A$17,0)),0))} | I36: =IF(A36="","",IF(G36="Sim",Config!$E$14,0)+IF(H36="Sim",Config!$E$15,0)) | K36: =IF(OR(A36="",L36="Inativo"),"",N(F36)*(1-N(J36))+N(I36)) | O36: =IF(AND(A36<>"",D36=""),ROW(),"") | P36: =IF(A36="","",COUNTIF($A$2:$A$301,"<"&A36)+COUNTIF($A$2:A36,A36))
F37: {=IF(B37="","",IFERROR(INDEX(Config!$B$14:$B$17,MATCH(B37,Config!$A$14:$A$17,0)),0))} | I37: =IF(A37="","",IF(G37="Sim",Config!$E$14,0)+IF(H37="Sim",Config!$E$15,0)) | K37: =IF(OR(A37="",L37="Inativo"),"",N(F37)*(1-N(J37))+N(I37)) | O37: =IF(AND(A37<>"",D37=""),ROW(),"") | P37: =IF(A37="","",COUNTIF($A$2:$A$301,"<"&A37)+COUNTIF($A$2:A37,A37))
... F301: {=IF(B301="","",IFERROR(INDEX(Config!$B$14:$B$17,MATCH(B301,Config!$A$14:$A$17,0)),0))} | I301: =IF(A301="","",IF(G301="Sim",Config!$E$14,0)+IF(H301="Sim",Config!$E$15,0)) | K301: =IF(OR(A301="",L301="Inativo"),"",N(F301)*(1-N(J301))+N(I301)) | O301: =IF(AND(A301<>"",D301=""),ROW(),"") | P301: =IF(A301="","",COUNTIF($A$2:$A$301,"<"&A301)+COUNTIF($A$2:A301,A301))

Sheet Alunos A-Z
A1: ALUNOS EM ORDEM ALFABÉTICA – atualiza sozinha
A2: Só para consulta. Para cadastrar ou alterar, use a aba Alunos – o nome entra aqui automaticamente na posição certa.
A3: Nº | B3: Aluno | C3: Turma | D3: Responsável financeiro | E3: Judô? | F3: Balé? | G3: Valor do boleto | H3: Situação
A4: =IF(ISNA(MATCH(1,Alunos!$P$2:$P$301,0)),"",1) | B4: {=IFERROR(INDEX(Alunos!$A$2:$A$301,MATCH(1,Alunos!$P$2:$P$301,0))&"","")} | C4: {=IFERROR(INDEX(Alunos!$B$2:$B$301,MATCH(1,Alunos!$P$2:$P$301,0))&"","")} | D4: {=IFERROR(INDEX(Alunos!$C$2:$C$301,MATCH(1,Alunos!$P$2:$P$301,0))&"","")} | E4: {=IFERROR(INDEX(Alunos!$G$2:$G$301,MATCH(1,Alunos!$P$2:$P$301,0))&"","")} | F4: {=IFERROR(INDEX(Alunos!$H$2:$H$301,MATCH(1,Alunos!$P$2:$P$301,0))&"","")} | G4: {=IFERROR(INDEX(Alunos!$K$2:$K$301,MATCH(1,Alunos!$P$2:$P$301,0)),"")} | H4: {=IFERROR(INDEX(Alunos!$L$2:$L$301,MATCH(1,Alunos!$P$2:$P$301,0))&"","")}
A5: =IF(ISNA(MATCH(2,Alunos!$P$2:$P$301,0)),"",2) | B5: {=IFERROR(INDEX(Alunos!$A$2:$A$301,MATCH(2,Alunos!$P$2:$P$301,0))&"","")} | C5: {=IFERROR(INDEX(Alunos!$B$2:$B$301,MATCH(2,Alunos!$P$2:$P$301,0))&"","")} | D5: {=IFERROR(INDEX(Alunos!$C$2:$C$301,MATCH(2,Alunos!$P$2:$P$301,0))&"","")} | E5: {=IFERROR(INDEX(Alunos!$G$2:$G$301,MATCH(2,Alunos!$P$2:$P$301,0))&"","")} | F5: {=IFERROR(INDEX(Alunos!$H$2:$H$301,MATCH(2,Alunos!$P$2:$P$301,0))&"","")} | G5: {=IFERROR(INDEX(Alunos!$K$2:$K$301,MATCH(2,Alunos!$P$2:$P$301,0)),"")} | H5: {=IFERROR(INDEX(Alunos!$L$2:$L$301,MATCH(2,Alunos!$P$2:$P$301,0))&"","")}
A6: =IF(ISNA(MATCH(3,Alunos!$P$2:$P$301,0)),"",3) | B6: {=IFERROR(INDEX(Alunos!$A$2:$A$301,MATCH(3,Alunos!$P$2:$P$301,0))&"","")} | C6: {=IFERROR(INDEX(Alunos!$B$2:$B$301,MATCH(3,Alunos!$P$2:$P$301,0))&"","")} | D6: {=IFERROR(INDEX(Alunos!$C$2:$C$301,MATCH(3,Alunos!$P$2:$P$301,0))&"","")} | E6: {=IFERROR(INDEX(Alunos!$G$2:$G$301,MATCH(3,Alunos!$P$2:$P$301,0))&"","")} | F6: {=IFERROR(INDEX(Alunos!$H$2:$H$301,MATCH(3,Alunos!$P$2:$P$301,0))&"","")} | G6: {=IFERROR(INDEX(Alunos!$K$2:$K$301,MATCH(3,Alunos!$P$2:$P$301,0)),"")} | H6: {=IFERROR(INDEX(Alunos!$L$2:$L$301,MATCH(3,Alunos!$P$2:$P$301,0))&"","")}
A7: =IF(ISNA(MATCH(4,Alunos!$P$2:$P$301,0)),"",4) | B7: {=IFERROR(INDEX(Alunos!$A$2:$A$301,MATCH(4,Alunos!$P$2:$P$301,0))&"","")} | C7: {=IFERROR(INDEX(Alunos!$B$2:$B$301,MATCH(4,Alunos!$P$2:$P$301,0))&"","")} | D7: {=IFERROR(INDEX(Alunos!$C$2:$C$301,MATCH(4,Alunos!$P$2:$P$301,0))&"","")} | E7: {=IFERROR(INDEX(Alunos!$G$2:$G$301,MATCH(4,Alunos!$P$2:$P$301,0))&"","")} | F7: {=IFERROR(INDEX(Alunos!$H$2:$H$301,MATCH(4,Alunos!$P$2:$P$301,0))&"","")} | G7: {=IFERROR(INDEX(Alunos!$K$2:$K$301,MATCH(4,Alunos!$P$2:$P$301,0)),"")} | H7: {=IFERROR(INDEX(Alunos!$L$2:$L$301,MATCH(4,Alunos!$P$2:$P$301,0))&"","")}
A8: =IF(ISNA(MATCH(5,Alunos!$P$2:$P$301,0)),"",5) | B8: {=IFERROR(INDEX(Alunos!$A$2:$A$301,MATCH(5,Alunos!$P$2:$P$301,0))&"","")} | C8: {=IFERROR(INDEX(Alunos!$B$2:$B$301,MATCH(5,Alunos!$P$2:$P$301,0))&"","")} | D8: {=IFERROR(INDEX(Alunos!$C$2:$C$301,MATCH(5,Alunos!$P$2:$P$301,0))&"","")} | E8: {=IFERROR(INDEX(Alunos!$G$2:$G$301,MATCH(5,Alunos!$P$2:$P$301,0))&"","")} | F8: {=IFERROR(INDEX(Alunos!$H$2:$H$301,MATCH(5,Alunos!$P$2:$P$301,0))&"","")} | G8: {=IFERROR(INDEX(Alunos!$K$2:$K$301,MATCH(5,Alunos!$P$2:$P$301,0)),"")} | H8: {=IFERROR(INDEX(Alunos!$L$2:$L$301,MATCH(5,Alunos!$P$2:$P$301,0))&"","")}
A9: =IF(ISNA(MATCH(6,Alunos!$P$2:$P$301,0)),"",6) | B9: {=IFERROR(INDEX(Alunos!$A$2:$A$301,MATCH(6,Alunos!$P$2:$P$301,0))&"","")} | C9: {=IFERROR(INDEX(Alunos!$B$2:$B$301,MATCH(6,Alunos!$P$2:$P$301,0))&"","")} | D9: {=IFERROR(INDEX(Alunos!$C$2:$C$301,MATCH(6,Alunos!$P$2:$P$301,0))&"","")} | E9: {=IFERROR(INDEX(Alunos!$G$2:$G$301,MATCH(6,Alunos!$P$2:$P$301,0))&"","")} | F9: {=IFERROR(INDEX(Alunos!$H$2:$H$301,MATCH(6,Alunos!$P$2:$P$301,0))&"","")} | G9: {=IFERROR(INDEX(Alunos!$K$2:$K$301,MATCH(6,Alunos!$P$2:$P$301,0)),"")} | H9: {=IFERROR(INDEX(Alunos!$L$2:$L$301,MATCH(6,Alunos!$P$2:$P$301,0))&"","")}
A10: =IF(ISNA(MATCH(7,Alunos!$P$2:$P$301,0)),"",7) | B10: {=IFERROR(INDEX(Alunos!$A$2:$A$301,MATCH(7,Alunos!$P$2:$P$301,0))&"","")} | C10: {=IFERROR(INDEX(Alunos!$B$2:$B$301,MATCH(7,Alunos!$P$2:$P$301,0))&"","")} | D10: {=IFERROR(INDEX(Alunos!$C$2:$C$301,MATCH(7,Alunos!$P$2:$P$301,0))&"","")} | E10: {=IFERROR(INDEX(Alunos!$G$2:$G$301,MATCH(7,Alunos!$P$2:$P$301,0))&"","")} | F10: {=IFERROR(INDEX(Alunos!$H$2:$H$301,MATCH(7,Alunos!$P$2:$P$301,0))&"","")} | G10: {=IFERROR(INDEX(Alunos!$K$2:$K$301,MATCH(7,Alunos!$P$2:$P$301,0)),"")} | H10: {=IFERROR(INDEX(Alunos!$L$2:$L$301,MATCH(7,Alunos!$P$2:$P$301,0))&"","")}
A11: =IF(ISNA(MATCH(8,Alunos!$P$2:$P$301,0)),"",8) | B11: {=IFERROR(INDEX(Alunos!$A$2:$A$301,MATCH(8,Alunos!$P$2:$P$301,0))&"","")} | C11: {=IFERROR(INDEX(Alunos!$B$2:$B$301,MATCH(8,Alunos!$P$2:$P$301,0))&"","")} | D11: {=IFERROR(INDEX(Alunos!$C$2:$C$301,MATCH(8,Alunos!$P$2:$P$301,0))&"","")} | E11: {=IFERROR(INDEX(Alunos!$G$2:$G$301,MATCH(8,Alunos!$P$2:$P$301,0))&"","")} | F11: {=IFERROR(INDEX(Alunos!$H$2:$H$301,MATCH(8,Alunos!$P$2:$P$301,0))&"","")} | G11: {=IFERROR(INDEX(Alunos!$K$2:$K$301,MATCH(8,Alunos!$P$2:$P$301,0)),"")} | H11: {=IFERROR(INDEX(Alunos!$L$2:$L$301,MATCH(8,Alunos!$P$2:$P$301,0))&"","")}
A12: =IF(ISNA(MATCH(9,Alunos!$P$2:$P$301,0)),"",9) | B12: {=IFERROR(INDEX(Alunos!$A$2:$A$301,MATCH(9,Alunos!$P$2:$P$301,0))&"","")} | C12: {=IFERROR(INDEX(Alunos!$B$2:$B$301,MATCH(9,Alunos!$P$2:$P$301,0))&"","")} | D12: {=IFERROR(INDEX(Alunos!$C$2:$C$301,MATCH(9,Alunos!$P$2:$P$301,0))&"","")} | E12: {=IFERROR(INDEX(Alunos!$G$2:$G$301,MATCH(9,Alunos!$P$2:$P$301,0))&"","")} | F12: {=IFERROR(INDEX(Alunos!$H$2:$H$301,MATCH(9,Alunos!$P$2:$P$301,0))&"","")} | G12: {=IFERROR(INDEX(Alunos!$K$2:$K$301,MATCH(9,Alunos!$P$2:$P$301,0)),"")} | H12: {=IFERROR(INDEX(Alunos!$L$2:$L$301,MATCH(9,Alunos!$P$2:$P$301,0))&"","")}
A13: =IF(ISNA(MATCH(10,Alunos!$P$2:$P$301,0)),"",10) | B13: {=IFERROR(INDEX(Alunos!$A$2:$A$301,MATCH(10,Alunos!$P$2:$P$301,0))&"","")} | C13: {=IFERROR(INDEX(Alunos!$B$2:$B$301,MATCH(10,Alunos!$P$2:$P$301,0))&"","")} | D13: {=IFERROR(INDEX(Alunos!$C$2:$C$301,MATCH(10,Alunos!$P$2:$P$301,0))&"","")} | E13: {=IFERROR(INDEX(Alunos!$G$2:$G$301,MATCH(10,Alunos!$P$2:$P$301,0))&"","")} | F13: {=IFERROR(INDEX(Alunos!$H$2:$H$301,MATCH(10,Alunos!$P$2:$P$301,0))&"","")} | G13: {=IFERROR(INDEX(Alunos!$K$2:$K$301,MATCH(10,Alunos!$P$2:$P$301,0)),"")} | H13: {=IFERROR(INDEX(Alunos!$L$2:$L$301,MATCH(10,Alunos!$P$2:$P$301,0))&"","")}
A14: =IF(ISNA(MATCH(11,Alunos!$P$2:$P$301,0)),"",11) | B14: {=IFERROR(INDEX(Alunos!$A$2:$A$301,MATCH(11,Alunos!$P$2:$P$301,0))&"","")} | C14: {=IFERROR(INDEX(Alunos!$B$2:$B$301,MATCH(11,Alunos!$P$2:$P$301,0))&"","")} | D14: {=IFERROR(INDEX(Alunos!$C$2:$C$301,MATCH(11,Alunos!$P$2:$P$301,0))&"","")} | E14: {=IFERROR(INDEX(Alunos!$G$2:$G$301,MATCH(11,Alunos!$P$2:$P$301,0))&"","")} | F14: {=IFERROR(INDEX(Alunos!$H$2:$H$301,MATCH(11,Alunos!$P$2:$P$301,0))&"","")} | G14: {=IFERROR(INDEX(Alunos!$K$2:$K$301,MATCH(11,Alunos!$P$2:$P$301,0)),"")} | H14: {=IFERROR(INDEX(Alunos!$L$2:$L$301,MATCH(11,Alunos!$P$2:$P$301,0))&"","")}
A15: =IF(ISNA(MATCH(12,Alunos!$P$2:$P$301,0)),"",12) | B15: {=IFERROR(INDEX(Alunos!$A$2:$A$301,MATCH(12,Alunos!$P$2:$P$301,0))&"","")} | C15: {=IFERROR(INDEX(Alunos!$B$2:$B$301,MATCH(12,Alunos!$P$2:$P$301,0))&"","")} | D15: {=IFERROR(INDEX(Alunos!$C$2:$C$301,MATCH(12,Alunos!$P$2:$P$301,0))&"","")} | E15: {=IFERROR(INDEX(Alunos!$G$2:$G$301,MATCH(12,Alunos!$P$2:$P$301,0))&"","")} | F15: {=IFERROR(INDEX(Alunos!$H$2:$H$301,MATCH(12,Alunos!$P$2:$P$301,0))&"","")} | G15: {=IFERROR(INDEX(Alunos!$K$2:$K$301,MATCH(12,Alunos!$P$2:$P$301,0)),"")} | H15: {=IFERROR(INDEX(Alunos!$L$2:$L$301,MATCH(12,Alunos!$P$2:$P$301,0))&"","")}
A16: =IF(ISNA(MATCH(13,Alunos!$P$2:$P$301,0)),"",13) | B16: {=IFERROR(INDEX(Alunos!$A$2:$A$301,MATCH(13,Alunos!$P$2:$P$301,0))&"","")} | C16: {=IFERROR(INDEX(Alunos!$B$2:$B$301,MATCH(13,Alunos!$P$2:$P$301,0))&"","")} | D16: {=IFERROR(INDEX(Alunos!$C$2:$C$301,MATCH(13,Alunos!$P$2:$P$301,0))&"","")} | E16: {=IFERROR(INDEX(Alunos!$G$2:$G$301,MATCH(13,Alunos!$P$2:$P$301,0))&"","")} | F16: {=IFERROR(INDEX(Alunos!$H$2:$H$301,MATCH(13,Alunos!$P$2:$P$301,0))&"","")} | G16: {=IFERROR(INDEX(Alunos!$K$2:$K$301,MATCH(13,Alunos!$P$2:$P$301,0)),"")} | H16: {=IFERROR(INDEX(Alunos!$L$2:$L$301,MATCH(13,Alunos!$P$2:$P$301,0))&"","")}
